Workbook

Sheet DIEU_KHIEN
A1: TRUNG TÂM LUYỆN THI - ĐIỀU KHIỂN KẾ TOÁN
A3: Thiết lập | B3: Giá trị | D3: QUY TRÌNH THÁNG MỚI
A4: Tháng làm việc | B4: 46235 | D4: 1 | E4: Nhập tháng làm việc tại B4 (ngày đầu tháng, ví dụ 01/08/2026)
A5: % trích quỹ | B5: 0.1 | D5: 2 | E5: Giữ 01_HocSinh.xlsx, 02_GiangVien.xlsx, 03_KeToan.xlsx trong cùng một thư mục
A6: % lương GV mặc định | B6: 0.5 | D6: 3 | E6: Mở 03_KeToan.xlsx trước, sau đó mở 01_HocSinh.xlsx và 02_GiangVien.xlsx; cho phép Update Links
A7: Nguyễn Mạnh Cường | B7: 0.5 | D7: 4 | E7: CHUYEN_THANG: chép Giảm chuyển tháng sau → Giảm từ tháng trước
A8: Đào Văn Hùng | B8: 0.5 | D8: 5 | E8: Xóa điểm danh cũ + buổi GV dạy cũ khi tạo tháng mới
A9: Quỹ đầu kỳ | B9: 0 | D9: 6 | E9: Xóa Đã thu / thưởng-phạt / thu-chi cũ khi tạo tháng mới
A10: Chi từ quỹ | B10: 0 | D10: 7 | E10: Kiểm tra KIEM_TRA_HE_THONG và TONG_QUAN trước khi vận hành

Sheet DANH_MUC_LOP
A1: DANH MỤC LỚP - CẤU HÌNH TRUNG TÂM
A3: Slot | B3: Mã lớp | C3: Tên lớp | D3: Khối | E3: Môn | F3: Học phí/buổi | G3: T2 | H3: T3 | I3: T4 | J3: T5 | K3: T6 | L3: T7 | M3: CN | N3: Cách thu | O3: % lương GV | P3: Trạng thái | Q3: Ghi chú | R3: Số buổi kế hoạch | S3: GV chính | T3: Trợ giảng
A4: 1 | B4: L06 | C4: Lớp 6 Thầy Cường | D4: 6 | E4: Toán | F4: 50000 | G4: Không | H4: Không | I4: Không | J4: Có | K4: Không | L4: Không | M4: Có | N4: Theo buổi | O4: 0.5 | P4: Hoạt động | Q4: Nguồn T8 rõ 1 buổi; chưa có dữ liệu thứ học | R4: =IF(B4="","",SUM(IF(G4="Có",MAX(0,1+INT((DAY(EOMONTH(DIEU_KHIEN!$B$4,0))-(1+MOD(1-WEEKDAY(DIEU_KHIEN!$B$4,2),7)))/7)),0),IF(H4="Có",MAX(0,1+INT((DAY(EOMONTH(DIEU_KHIEN!$B$4,0))-(1+MOD(2-WEEKDAY(DIEU_KHIEN!$B$4,2),7)))/7)),0),IF(I4="Có",MAX(0,1+INT((DAY(EOMONTH(DIEU_KHIEN!$B$4,0))-(1+MOD(3-WEEKDAY(DIEU_KHIEN!$B$4,2),7)))/7)),0),IF(J4="Có",MAX(0,1+INT((DAY(EOMONTH(DIEU_KHIEN!$B$4,0))-(1+MOD(4-WEEKDAY(DIEU_KHIEN!$B$4,2),7)))/7)),0),IF(K4="Có",MAX(0,1+INT((DAY(EOMONTH(DIEU_KHIEN!$B$4,0))-(1+MOD(5-WEEKDAY(DIEU_KHIEN!$B$4,2),7)))/7)),0),IF(L4="Có",MAX(0,1+INT((DAY(EOMONTH(DIEU_KHIEN!$B$4,0))-(1+MOD(6-WEEKDAY(DIEU_KHIEN!$B$4,2),7)))/7)),0),IF(M4="Có",MAX(0,1+INT((DAY(EOMONTH(DIEU_KHIEN!$B$4,0))-(1+MOD(7-WEEKDAY(DIEU_KHIEN!$B$4,2),7)))/7)),0))) -> 9 | S4: Nguyễn Mạnh Cường | T4: Nguyễn Hà Anh
A5: 2 | B5: L07 | C5: Toán 7 Thầy Cường | D5: 7 | E5: Toán | F5: 50000 | G5: Không | H5: Có | I5: Không | J5: Không | K5: Có | L5: Không | M5: Không | N5: Theo buổi | O5: 0.5 | P5: Hoạt động | Q5: T8: chỉ lấy block có nhận xét thực tế; chưa rõ thứ học | R5: =IF(B5="","",SUM(IF(G5="Có",MAX(0,1+INT((DAY(EOMONTH(DIEU_KHIEN!$B$4,0))-(1+MOD(1-WEEKDAY(DIEU_KHIEN!$B$4,2),7)))/7)),0),IF(H5="Có",MAX(0,1+INT((DAY(EOMONTH(DIEU_KHIEN!$B$4,0))-(1+MOD(2-WEEKDAY(DIEU_KHIEN!$B$4,2),7)))/7)),0),IF(I5="Có",MAX(0,1+INT((DAY(EOMONTH(DIEU_KHIEN!$B$4,0))-(1+MOD(3-WEEKDAY(DIEU_KHIEN!$B$4,2),7)))/7)),0),IF(J5="Có",MAX(0,1+INT((DAY(EOMONTH(DIEU_KHIEN!$B$4,0))-(1+MOD(4-WEEKDAY(DIEU_KHIEN!$B$4,2),7)))/7)),0),IF(K5="Có",MAX(0,1+INT((DAY(EOMONTH(DIEU_KHIEN!$B$4,0))-(1+MOD(5-WEEKDAY(DIEU_KHIEN!$B$4,2),7)))/7)),0),IF(L5="Có",MAX(0,1+INT((DAY(EOMONTH(DIEU_KHIEN!$B$4,0))-(1+MOD(6-WEEKDAY(DIEU_KHIEN!$B$4,2),7)))/7)),0),IF(M5="Có",MAX(0,1+INT((DAY(EOMONTH(DIEU_KHIEN!$B$4,0))-(1+MOD(7-WEEKDAY(DIEU_KHIEN!$B$4,2),7)))/7)),0))) -> 8 | S5: Nguyễn Mạnh Cường | T5: Đào Quang Duy
A6: 3 | B6: L08 | C6: Toán 8 Thầy Cường | D6: 8 | E6: Toán | F6: 50000 | G6: Không | H6: Có | I6: Không | J6: Không | K6: Không | L6: Không | M6: Có | N6: Theo buổi | O6: 0.5 | P6: Hoạt động | Q6: Chưa có điểm danh T8 đủ bằng chứng | R6: =IF(B6="","",SUM(IF(G6="Có",MAX(0,1+INT((DAY(EOMONTH(DIEU_KHIEN!$B$4,0))-(1+MOD(1-WEEKDAY(DIEU_KHIEN!$B$4,2),7)))/7)),0),IF(H6="Có",MAX(0,1+INT((DAY(EOMONTH(DIEU_KHIEN!$B$4,0))-(1+MOD(2-WEEKDAY(DIEU_KHIEN!$B$4,2),7)))/7)),0),IF(I6="Có",MAX(0,1+INT((DAY(EOMONTH(DIEU_KHIEN!$B$4,0))-(1+MOD(3-WEEKDAY(DIEU_KHIEN!$B$4,2),7)))/7)),0),IF(J6="Có",MAX(0,1+INT((DAY(EOMONTH(DIEU_KHIEN!$B$4,0))-(1+MOD(4-WEEKDAY(DIEU_KHIEN!$B$4,2),7)))/7)),0),IF(K6="Có",MAX(0,1+INT((DAY(EOMONTH(DIEU_KHIEN!$B$4,0))-(1+MOD(5-WEEKDAY(DIEU_KHIEN!$B$4,2),7)))/7)),0),IF(L6="Có",MAX(0,1+INT((DAY(EOMONTH(DIEU_KHIEN!$B$4,0))-(1+MOD(6-WEEKDAY(DIEU_KHIEN!$B$4,2),7)))/7)),0),IF(M6="Có",MAX(0,1+INT((DAY(EOMONTH(DIEU_KHIEN!$B$4,0))-(1+MOD(7-WEEKDAY(DIEU_KHIEN!$B$4,2),7)))/7)),0))) -> 9 | S6: Nguyễn Mạnh Cường | T6: Đào Phương Anh
A7: 4 | B7: L09 | C7: Toán 9 Thầy Cường | D7: 9 | E7: Toán | F7: 60000 | G7: Có | H7: Không | I7: Không | J7: Có | K7: Không | L7: Không | M7: Không | N7: Thu trước | O7: 0.5 | P7: Hoạt động | Q7: Nguồn ghi 9 buổi T8 dự tính; chưa rõ thứ học | R7: 9 | S7: Nguyễn Mạnh Cường | T7: Đào Phương Anh
A8: 5 | G8: Không | H8: Không | I8: Không | J8: Không | K8: Không | L8: Không | M8: Không | N8: Theo buổi | P8: Chưa dùng | R8: =IF(B8="","",SUM(IF(G8="Có",MAX(0,1+INT((DAY(EOMONTH(DIEU_KHIEN!$B$4,0))-(1+MOD(1-WEEKDAY(DIEU_KHIEN!$B$4,2),7)))/7)),0),IF(H8="Có",MAX(0,1+INT((DAY(EOMONTH(DIEU_KHIEN!$B$4,0))-(1+MOD(2-WEEKDAY(DIEU_KHIEN!$B$4,2),7)))/7)),0),IF(I8="Có",MAX(0,1+INT((DAY(EOMONTH(DIEU_KHIEN!$B$4,0))-(1+MOD(3-WEEKDAY(DIEU_KHIEN!$B$4,2),7)))/7)),0),IF(J8="Có",MAX(0,1+INT((DAY(EOMONTH(DIEU_KHIEN!$B$4,0))-(1+MOD(4-WEEKDAY(DIEU_KHIEN!$B$4,2),7)))/7)),0),IF(K8="Có",MAX(0,1+INT((DAY(EOMONTH(DIEU_KHIEN!$B$4,0))-(1+MOD(5-WEEKDAY(DIEU_KHIEN!$B$4,2),7)))/7)),0),IF(L8="Có",MAX(0,1+INT((DAY(EOMONTH(DIEU_KHIEN!$B$4,0))-(1+MOD(6-WEEKDAY(DIEU_KHIEN!$B$4,2),7)))/7)),0),IF(M8="Có",MAX(0,1+INT((DAY(EOMONTH(DIEU_KHIEN!$B$4,0))-(1+MOD(7-WEEKDAY(DIEU_KHIEN!$B$4,2),7)))/7)),0)))
A9: 6 | G9: Không | H9: Không | I9: Không | J9: Không | K9: Không | L9: Không | M9: Không | N9: Theo buổi | P9: Chưa dùng | R9: =IF(B9="","",SUM(IF(G9="Có",MAX(0,1+INT((DAY(EOMONTH(DIEU_KHIEN!$B$4,0))-(1+MOD(1-WEEKDAY(DIEU_KHIEN!$B$4,2),7)))/7)),0),IF(H9="Có",MAX(0,1+INT((DAY(EOMONTH(DIEU_KHIEN!$B$4,0))-(1+MOD(2-WEEKDAY(DIEU_KHIEN!$B$4,2),7)))/7)),0),IF(I9="Có",MAX(0,1+INT((DAY(EOMONTH(DIEU_KHIEN!$B$4,0))-(1+MOD(3-WEEKDAY(DIEU_KHIEN!$B$4,2),7)))/7)),0),IF(J9="Có",MAX(0,1+INT((DAY(EOMONTH(DIEU_KHIEN!$B$4,0))-(1+MOD(4-WEEKDAY(DIEU_KHIEN!$B$4,2),7)))/7)),0),IF(K9="Có",MAX(0,1+INT((DAY(EOMONTH(DIEU_KHIEN!$B$4,0))-(1+MOD(5-WEEKDAY(DIEU_KHIEN!$B$4,2),7)))/7)),0),IF(L9="Có",MAX(0,1+INT((DAY(EOMONTH(DIEU_KHIEN!$B$4,0))-(1+MOD(6-WEEKDAY(DIEU_KHIEN!$B$4,2),7)))/7)),0),IF(M9="Có",MAX(0,1+INT((DAY(EOMONTH(DIEU_KHIEN!$B$4,0))-(1+MOD(7-WEEKDAY(DIEU_KHIEN!$B$4,2),7)))/7)),0)))
A10: 7 | G10: Không | H10: Không | I10: Không | J10: Không | K10: Không | L10: Không | M10: Không | N10: Theo buổi | P10: Chưa dùng | R10: =IF(B10="","",SUM(IF(G10="Có",MAX(0,1+INT((DAY(EOMONTH(DIEU_KHIEN!$B$4,0))-(1+MOD(1-WEEKDAY(DIEU_KHIEN!$B$4,2),7)))/7)),0),IF(H10="Có",MAX(0,1+INT((DAY(EOMONTH(DIEU_KHIEN!$B$4,0))-(1+MOD(2-WEEKDAY(DIEU_KHIEN!$B$4,2),7)))/7)),0),IF(I10="Có",MAX(0,1+INT((DAY(EOMONTH(DIEU_KHIEN!$B$4,0))-(1+MOD(3-WEEKDAY(DIEU_KHIEN!$B$4,2),7)))/7)),0),IF(J10="Có",MAX(0,1+INT((DAY(EOMONTH(DIEU_KHIEN!$B$4,0))-(1+MOD(4-WEEKDAY(DIEU_KHIEN!$B$4,2),7)))/7)),0),IF(K10="Có",MAX(0,1+INT((DAY(EOMONTH(DIEU_KHIEN!$B$4,0))-(1+MOD(5-WEEKDAY(DIEU_KHIEN!$B$4,2),7)))/7)),0),IF(L10="Có",MAX(0,1+INT((DAY(EOMONTH(DIEU_KHIEN!$B$4,0))-(1+MOD(6-WEEKDAY(DIEU_KHIEN!$B$4,2),7)))/7)),0),IF(M10="Có",MAX(0,1+INT((DAY(EOMONTH(DIEU_KHIEN!$B$4,0))-(1+MOD(7-WEEKDAY(DIEU_KHIEN!$B$4,2),7)))/7)),0)))
A11: 8 | G11: Không | H11: Không | I11: Không | J11: Không | K11: Không | L11: Không | M11: Không | N11: Theo buổi | P11: Chưa dùng | R11: =IF(B11="","",SUM(IF(G11="Có",MAX(0,1+INT((DAY(EOMONTH(DIEU_KHIEN!$B$4,0))-(1+MOD(1-WEEKDAY(DIEU_KHIEN!$B$4,2),7)))/7)),0),IF(H11="Có",MAX(0,1+INT((DAY(EOMONTH(DIEU_KHIEN!$B$4,0))-(1+MOD(2-WEEKDAY(DIEU_KHIEN!$B$4,2),7)))/7)),0),IF(I11="Có",MAX(0,1+INT((DAY(EOMONTH(DIEU_KHIEN!$B$4,0))-(1+MOD(3-WEEKDAY(DIEU_KHIEN!$B$4,2),7)))/7)),0),IF(J11="Có",MAX(0,1+INT((DAY(EOMONTH(DIEU_KHIEN!$B$4,0))-(1+MOD(4-WEEKDAY(DIEU_KHIEN!$B$4,2),7)))/7)),0),IF(K11="Có",MAX(0,1+INT((DAY(EOMONTH(DIEU_KHIEN!$B$4,0))-(1+MOD(5-WEEKDAY(DIEU_KHIEN!$B$4,2),7)))/7)),0),IF(L11="Có",MAX(0,1+INT((DAY(EOMONTH(DIEU_KHIEN!$B$4,0))-(1+MOD(6-WEEKDAY(DIEU_KHIEN!$B$4,2),7)))/7)),0),IF(M11="Có",MAX(0,1+INT((DAY(EOMONTH(DIEU_KHIEN!$B$4,0))-(1+MOD(7-WEEKDAY(DIEU_KHIEN!$B$4,2),7)))/7)),0)))
A12: 9 | G12: Không | H12: Không | I12: Không | J12: Không | K12: Không | L12: Không | M12: Không | N12: Theo buổi | P12: Chưa dùng | R12: =IF(B12="","",SUM(IF(G12="Có",MAX(0,1+INT((DAY(EOMONTH(DIEU_KHIEN!$B$4,0))-(1+MOD(1-WEEKDAY(DIEU_KHIEN!$B$4,2),7)))/7)),0),IF(H12="Có",MAX(0,1+INT((DAY(EOMONTH(DIEU_KHIEN!$B$4,0))-(1+MOD(2-WEEKDAY(DIEU_KHIEN!$B$4,2),7)))/7)),0),IF(I12="Có",MAX(0,1+INT((DAY(EOMONTH(DIEU_KHIEN!$B$4,0))-(1+MOD(3-WEEKDAY(DIEU_KHIEN!$B$4,2),7)))/7)),0),IF(J12="Có",MAX(0,1+INT((DAY(EOMONTH(DIEU_KHIEN!$B$4,0))-(1+MOD(4-WEEKDAY(DIEU_KHIEN!$B$4,2),7)))/7)),0),IF(K12="Có",MAX(0,1+INT((DAY(EOMONTH(DIEU_KHIEN!$B$4,0))-(1+MOD(5-WEEKDAY(DIEU_KHIEN!$B$4,2),7)))/7)),0),IF(L12="Có",MAX(0,1+INT((DAY(EOMONTH(DIEU_KHIEN!$B$4,0))-(1+MOD(6-WEEKDAY(DIEU_KHIEN!$B$4,2),7)))/7)),0),IF(M12="Có",MAX(0,1+INT((DAY(EOMONTH(DIEU_KHIEN!$B$4,0))-(1+MOD(7-WEEKDAY(DIEU_KHIEN!$B$4,2),7)))/7)),0)))
A13: 10 | G13: Không | H13: Không | I13: Không | J13: Không | K13: Không | L13: Không | M13: Không | N13: Theo buổi | P13: Chưa dùng | R13: =IF(B13="","",SUM(IF(G13="Có",MAX(0,1+INT((DAY(EOMONTH(DIEU_KHIEN!$B$4,0))-(1+MOD(1-WEEKDAY(DIEU_KHIEN!$B$4,2),7)))/7)),0),IF(H13="Có",MAX(0,1+INT((DAY(EOMONTH(DIEU_KHIEN!$B$4,0))-(1+MOD(2-WEEKDAY(DIEU_KHIEN!$B$4,2),7)))/7)),0),IF(I13="Có",MAX(0,1+INT((DAY(EOMONTH(DIEU_KHIEN!$B$4,0))-(1+MOD(3-WEEKDAY(DIEU_KHIEN!$B$4,2),7)))/7)),0),IF(J13="Có",MAX(0,1+INT((DAY(EOMONTH(DIEU_KHIEN!$B$4,0))-(1+MOD(4-WEEKDAY(DIEU_KHIEN!$B$4,2),7)))/7)),0),IF(K13="Có",MAX(0,1+INT((DAY(EOMONTH(DIEU_KHIEN!$B$4,0))-(1+MOD(5-WEEKDAY(DIEU_KHIEN!$B$4,2),7)))/7)),0),IF(L13="Có",MAX(0,1+INT((DAY(EOMONTH(DIEU_KHIEN!$B$4,0))-(1+MOD(6-WEEKDAY(DIEU_KHIEN!$B$4,2),7)))/7)),0),IF(M13="Có",MAX(0,1+INT((DAY(EOMONTH(DIEU_KHIEN!$B$4,0))-(1+MOD(7-WEEKDAY(DIEU_KHIEN!$B$4,2),7)))/7)),0)))
A14: 11 | G14: Không | H14: Không | I14: Không | J14: Không | K14: Không | L14: Không | M14: Không | N14: Theo buổi | P14: Chưa dùng | R14: =IF(B14="","",SUM(IF(G14="Có",MAX(0,1+INT((DAY(EOMONTH(DIEU_KHIEN!$B$4,0))-(1+MOD(1-WEEKDAY(DIEU_KHIEN!$B$4,2),7)))/7)),0),IF(H14="Có",MAX(0,1+INT((DAY(EOMONTH(DIEU_KHIEN!$B$4,0))-(1+MOD(2-WEEKDAY(DIEU_KHIEN!$B$4,2),7)))/7)),0),IF(I14="Có",MAX(0,1+INT((DAY(EOMONTH(DIEU_KHIEN!$B$4,0))-(1+MOD(3-WEEKDAY(DIEU_KHIEN!$B$4,2),7)))/7)),0),IF(J14="Có",MAX(0,1+INT((DAY(EOMONTH(DIEU_KHIEN!$B$4,0))-(1+MOD(4-WEEKDAY(DIEU_KHIEN!$B$4,2),7)))/7)),0),IF(K14="Có",MAX(0,1+INT((DAY(EOMONTH(DIEU_KHIEN!$B$4,0))-(1+MOD(5-WEEKDAY(DIEU_KHIEN!$B$4,2),7)))/7)),0),IF(L14="Có",MAX(0,1+INT((DAY(EOMONTH(DIEU_KHIEN!$B$4,0))-(1+MOD(6-WEEKDAY(DIEU_KHIEN!$B$4,2),7)))/7)),0),IF(M14="Có",MAX(0,1+INT((DAY(EOMONTH(DIEU_KHIEN!$B$4,0))-(1+MOD(7-WEEKDAY(DIEU_KHIEN!$B$4,2),7)))/7)),0)))
A15: 12 | G15: Không | H15: Không | I15: Không | J15: Không | K15: Không | L15: Không | M15: Không | N15: Theo buổi | P15: Chưa dùng | R15: =IF(B15="","",SUM(IF(G15="Có",MAX(0,1+INT((DAY(EOMONTH(DIEU_KHIEN!$B$4,0))-(1+MOD(1-WEEKDAY(DIEU_KHIEN!$B$4,2),7)))/7)),0),IF(H15="Có",MAX(0,1+INT((DAY(EOMONTH(DIEU_KHIEN!$B$4,0))-(1+MOD(2-WEEKDAY(DIEU_KHIEN!$B$4,2),7)))/7)),0),IF(I15="Có",MAX(0,1+INT((DAY(EOMONTH(DIEU_KHIEN!$B$4,0))-(1+MOD(3-WEEKDAY(DIEU_KHIEN!$B$4,2),7)))/7)),0),IF(J15="Có",MAX(0,1+INT((DAY(EOMONTH(DIEU_KHIEN!$B$4,0))-(1+MOD(4-WEEKDAY(DIEU_KHIEN!$B$4,2),7)))/7)),0),IF(K15="Có",MAX(0,1+INT((DAY(EOMONTH(DIEU_KHIEN!$B$4,0))-(1+MOD(5-WEEKDAY(DIEU_KHIEN!$B$4,2),7)))/7)),0),IF(L15="Có",MAX(0,1+INT((DAY(EOMONTH(DIEU_KHIEN!$B$4,0))-(1+MOD(6-WEEKDAY(DIEU_KHIEN!$B$4,2),7)))/7)),0),IF(M15="Có",MAX(0,1+INT((DAY(EOMONTH(DIEU_KHIEN!$B$4,0))-(1+MOD(7-WEEKDAY(DIEU_KHIEN!$B$4,2),7)))/7)),0)))

Sheet THUONG_HOC_SINH
A1: THƯỞNG HỌC SINH
A3: Mã lớp | B3: Mã HS | C3: Họ tên | D3: Tiền thưởng | E3: Lý do | F3: Ghi chú

Sheet THU_CHI
A1: THU / CHI KHÁC
A3: Ngày | B3: Loại | C3: Nhóm | D3: Mã lớp | E3: Nội dung | F3: Số tiền | G3: Ghi chú
B4: Chi | F4: =200000*4 -> 800000
B5: Chi | F5: 5470898
B6: Chi
B7: Chi
B8: Chi
B9: Chi
B10: Chi
B11: Chi
B12: Chi
B13: Chi
B14: Chi
B15: Chi
B16: Chi
B17: Chi
... B123: Chi

Sheet CHUYEN_THANG
A1: LỚP 9 - GIẢM HỌC PHÍ CHUYỂN THÁNG
A3: Mã lớp | B3: Mã HS | C3: Họ tên | D3: Giảm từ tháng trước | F3: Mã lớp | G3: Mã HS | H3: Họ tên | I3: Giảm chuyển tháng sau
A4: L09 | B4: HS09-004 | C4: Anh Trọng | D4: 60000 | F4: =KT_01!$B$4 -> L06 | G4: =KT_01!$A$14 -> HS06-001 | H4: =KT_01!$B$14 -> Đào Thị Kim Ngân | I4: =KT_01!$K$14 -> 0
A5: L09 | B5: HS09-007 | C5: Quân | D5: 60000 | F5: =KT_01!$B$4 -> L06 | G5: =KT_01!$A$15 -> HS06-002 | H5: =KT_01!$B$15 -> Đặng Phương Anh | I5: =KT_01!$K$15 -> 0
F6: =KT_01!$B$4 -> L06 | G6: =KT_01!$A$16 -> HS06-003 | H6: =KT_01!$B$16 -> Nguyễn Gia Bảo | I6: =KT_01!$K$16 -> 0
F7: =KT_01!$B$4 -> L06 | G7: =KT_01!$A$17 -> HS06-004 | H7: =KT_01!$B$17 -> Nguyễn Đặng Gia Bảo | I7: =KT_01!$K$17 -> 0
F8: =KT_01!$B$4 -> L06 | G8: =KT_01!$A$18 -> HS06-005 | H8: =KT_01!$B$18 -> Tuệ Lâm | I8: =KT_01!$K$18 -> 0
F9: =KT_01!$B$4 -> L06 | G9: =KT_01!$A$19 -> HS06-006 | H9: =KT_01!$B$19 -> Đặng Khánh Linh | I9: =KT_01!$K$19 -> 0
F10: =KT_01!$B$4 -> L06 | G10: =#REF! -> #REF! | H10: =#REF! -> #REF! | I10: =#REF! -> #REF!
F11: =KT_01!$B$4 -> L06 | G11: =KT_01!$A$20 -> HS06-007 | H11: =KT_01!$B$20 -> Nguyễn Ngọc Diệp | I11: =KT_01!$K$20 -> 0
F12: =KT_01!$B$4 -> L06 | G12: =KT_01!$A$21 -> HS06-008 | H12: =KT_01!$B$21 -> Nguyễn Ngọc Cẩm Tú | I12: =KT_01!$K$21 -> 0
F13: =KT_01!$B$4 -> L06 | G13: =KT_01!$A$22 -> HS06-009 | H13: =KT_01!$B$22 -> Đào Thế Hoàng | I13: =KT_01!$K$22 -> 0
F14: =KT_01!$B$4 -> L06 | G14: =KT_01!$A$23 -> HS06-010 | H14: =KT_01!$B$23 -> Đào Nguyễn Bình An | I14: =KT_01!$K$23 -> 0
F15: =KT_01!$B$4 -> L06 | G15: =KT_01!$A$24 -> HS06-011 | H15: =KT_01!$B$24 -> Nguyễn Trà My | I15: =KT_01!$K$24 -> 0
F16: =KT_01!$B$4 -> L06 | G16: =KT_01!$A$25 -> HS06-012 | H16: =KT_01!$B$25 -> Bảo Dũng | I16: =KT_01!$K$25 -> 0
F17: =KT_01!$B$4 -> L06 | G17: =KT_01!$A$26 -> HS06-013 | H17: =KT_01!$B$26 -> Đào Quang Minh | I17: =KT_01!$K$26 -> 0
F18: =KT_01!$B$4 -> L06 | G18: =KT_01!$A$27 -> HS06-014 | H18: =KT_01!$B$27 -> Duy | I18: =KT_01!$K$27 -> 0
F19: =KT_01!$B$4 -> L06 | G19: =KT_01!$A$28 -> HS06-015 | H19: =KT_01!$B$28 -> Phúc | I19: =KT_01!$K$28 -> 0
F20: =KT_01!$B$4 -> L06 | G20: =KT_01!$A$29 -> HS06-016 | H20: =KT_01!$B$29 -> Linh | I20: =KT_01!$K$29 -> 0
F21: =KT_01!$B$4 -> L06 | G21: =KT_01!$A$30 -> HS06-017 | H21: =KT_01!$B$30 -> Hân | I21: =KT_01!$K$30 -> 0
F22: =KT_01!$B$4 -> L06 | G22: =KT_01!$A$31 -> HS06-018 | H22: =KT_01!$B$31 -> Kiều Anh | I22: =KT_01!$K$31 -> 0
F23: =KT_01!$B$4 -> L06 | G23: =KT_01!$A$32 | H23: =KT_01!$B$32 | I23: =KT_01!$K$32
F24: =KT_01!$B$4 -> L06 | G24: =KT_01!$A$33 | H24: =KT_01!$B$33 | I24: =KT_01!$K$33
F25: =KT_01!$B$4 -> L06 | G25: =KT_01!$A$34 | H25: =KT_01!$B$34 | I25: =KT_01!$K$34
F26: =KT_01!$B$4 -> L06 | G26: =KT_01!$A$35 | H26: =KT_01!$B$35 | I26: =KT_01!$K$35
F27: =KT_01!$B$4 -> L06 | G27: =KT_01!$A$36 | H27: =KT_01!$B$36 | I27: =KT_01!$K$36
F28: =KT_01!$B$4 -> L06 | G28: =KT_01!$A$37 | H28: =KT_01!$B$37 | I28: =KT_01!$K$37
F29: =KT_01!$B$4 -> L06 | G29: =KT_01!$A$38 | H29: =KT_01!$B$38 | I29: =KT_01!$K$38
F30: =KT_01!$B$4 -> L06 | G30: =KT_01!$A$39 | H30: =KT_01!$B$39 | I30: =KT_01!$K$39
F31: =KT_01!$B$4 -> L06 | G31: =KT_01!$A$40 | H31: =KT_01!$B$40 | I31: =KT_01!$K$40
F32: =KT_01!$B$4 -> L06 | G32: =KT_01!$A$41 | H32: =KT_01!$B$41 | I32: =KT_01!$K$41
F33: =KT_01!$B$4 -> L06 | G33: =KT_01!$A$42 | H33: =KT_01!$B$42 | I33: =KT_01!$K$42
F34: =KT_02!$B$4 -> L07 | G34: =KT_02!$A$14 -> HS07-001 | H34: =KT_02!$B$14 -> Lê Ngọc Ánh | I34: =KT_02!$K$14 -> 0
F35: =KT_02!$B$4 -> L07 | G35: =KT_02!$A$15 -> HS07-002 | H35: =KT_02!$B$15 -> Nguyễn Thị Hồng Hạnh | I35: =KT_02!$K$15 -> 0
F36: =KT_02!$B$4 -> L07 | G36: =KT_02!$A$16 -> HS07-003 | H36: =KT_02!$B$16 -> Nguyễn Văn Phúc | I36: =KT_02!$K$16 -> 0
F37: =KT_02!$B$4 -> L07 | G37: =KT_02!$A$17 -> HS07-004 | H37: =KT_02!$B$17 -> Đào Thành Lê | I37: =KT_02!$K$17 -> 0
F38: =KT_02!$B$4 -> L07 | G38: =KT_02!$A$18 -> HS07-005 | H38: =KT_02!$B$18 -> Nguyễn Thành Công | I38: =KT_02!$K$18 -> 0
F39: =KT_02!$B$4 -> L07 | G39: =KT_02!$A$19 -> HS07-006 | H39: =KT_02!$B$19 -> Bùi Bảo Minh Anh | I39: =KT_02!$K$19 -> 0
F40: =KT_02!$B$4 -> L07 | G40: =KT_02!$A$20 -> HS07-007 | H40: =KT_02!$B$20 -> Cao Nhật Minh | I40: =KT_02!$K$20 -> 0
F41: =KT_02!$B$4 -> L07 | G41: =KT_02!$A$21 -> HS07-008 | H41: =KT_02!$B$21 -> Phạm Mạnh Hùng | I41: =KT_02!$K$21 -> 0
...

Sheet LUONG_GIANG_VIEN
A1: LƯƠNG GIẢNG VIÊN - % DOANH THU THEO LỚP
A3: Tháng | B3: Mã GV | C3: Họ tên | D3: Mã lớp | E3: Tên lớp | F3: Buổi GV dạy | G3: Buổi của lớp | H3: Doanh thu thực thu lớp | I3: % mặc định | J3: % điều chỉnh | K3: % áp dụng | L3: Tỷ lệ buổi | M3: Lương cơ sở | N3: Thưởng | O3: Phạt | P3: Thực nhận
A4: =IFERROR(PHAN_CONG!$A$4,"") -> 46235 | B4: =IFERROR(PHAN_CONG!$B$4,"") -> GV001 | C4: =IFERROR(PHAN_CONG!$C$5,"") -> Nguyễn Mạnh Cường | D4: =IFERROR(PHAN_CONG!$D$4,"") -> L06 | E4: =IFERROR(PHAN_CONG!$E$4,"") -> Lớp 6 Thầy Cường | F4: =IFERROR(PHAN_CONG!$F$4,"") -> 7 | G4: =IFERROR(PHAN_CONG!$F$4,"") -> 7 | H4: =IF(D4="","",SUMIF(TONG_HOP_LOP!$B$4:$B$15,D4,TONG_HOP_LOP!$G$4:$G$15)) -> 5025000 | I4: =IF(D4="","",IFERROR(VLOOKUP(D4,DANH_MUC_LOP!$B$4:$O$15,14,FALSE),DIEU_KHIEN!$B$6)) -> 0.5 | J4: 0.4 | K4: =IF(B4="","",IF(J4="",I4,J4)) -> 0.4 | L4: =IF(OR(F4="",G4=0),"",MIN(1,F4/G4)) -> 1 | M4: =IF(B4="","",H4*K4*L4) -> 2010000 | P4: =IF(B4="","",MAX(0,M4+N4-O4)) -> 2010000
A5: =IFERROR(PHAN_CONG!$A$5,"") -> 46235 | B5: =IFERROR(PHAN_CONG!$B$5,"") -> GV001 | C5: =IFERROR(PHAN_CONG!$C$5,"") -> Nguyễn Mạnh Cường | D5: =IFERROR(PHAN_CONG!$D$5,"") -> L07 | E5: =IFERROR(PHAN_CONG!$E$5,"") -> Toán 7 Thầy Cường | F5: =IFERROR(PHAN_CONG!$F$5,"") -> 7 | G5: =IFERROR(PHAN_CONG!$F$5,"") -> 7 | H5: =IF(D5="","",SUMIF(TONG_HOP_LOP!$B$4:$B$15,D5,TONG_HOP_LOP!$G$4:$G$15)) -> 2600000 | I5: =IF(D5="","",IFERROR(VLOOKUP(D5,DANH_MUC_LOP!$B$4:$O$15,14,FALSE),DIEU_KHIEN!$B$6)) -> 0.5 | J5: 0.4 | K5: =IF(B5="","",IF(J5="",I5,J5)) -> 0.4 | L5: =IF(OR(F5="",G5=0),"",MIN(1,F5/G5)) -> 1 | M5: =IF(B5="","",H5*K5*L5) -> 1040000 | P5: =IF(B5="","",MAX(0,M5+N5-O5)) -> 1040000
A6: =IFERROR(PHAN_CONG!$A$6,"") -> 46235 | B6: =IFERROR(PHAN_CONG!$B$6,"") -> GV001 | C6: =IFERROR(PHAN_CONG!$C$6,"") -> Nguyễn Mạnh Cường | D6: =IFERROR(PHAN_CONG!$D$6,"") -> L08 | E6: =IFERROR(PHAN_CONG!$E$6,"") -> Toán 8 Thầy Cường | F6: =IFERROR(PHAN_CONG!$F$6,"") -> 7 | G6: =IFERROR(PHAN_CONG!$F$6,"") -> 7 | H6: =IF(D6="","",SUMIF(TONG_HOP_LOP!$B$4:$B$15,D6,TONG_HOP_LOP!$G$4:$G$15)) -> 2000000 | I6: =IF(D6="","",IFERROR(VLOOKUP(D6,DANH_MUC_LOP!$B$4:$O$15,14,FALSE),DIEU_KHIEN!$B$6)) -> 0.5 | J6: 0.4 | K6: =IF(B6="","",IF(J6="",I6,J6)) -> 0.4 | L6: =IF(OR(F6="",G6=0),"",MIN(1,F6/G6)) -> 1 | M6: =IF(B6="","",H6*K6*L6) -> 800000 | P6: =IF(B6="","",MAX(0,M6+N6-O6)) -> 800000
A7: =IFERROR(PHAN_CONG!$A$7,"") -> 46235 | B7: =IFERROR(PHAN_CONG!$B$7,"") -> GV001 | C7: =IFERROR(PHAN_CONG!$C$7,"") -> Nguyễn Mạnh Cường | D7: =IFERROR(PHAN_CONG!$D$7,"") -> L09 | E7: =IFERROR(PHAN_CONG!$E$7,"") -> Toán 9 Thầy Cường | F7: =IFERROR(PHAN_CONG!$F$7,"") -> 7 | G7: =IFERROR(PHAN_CONG!$F$7,"") -> 7 | H7: =IF(D7="","",SUMIF(TONG_HOP_LOP!$B$4:$B$15,D7,TONG_HOP_LOP!$G$4:$G$15)) -> 4860000 | I7: =IF(D7="","",IFERROR(VLOOKUP(D7,DANH_MUC_LOP!$B$4:$O$15,14,FALSE),DIEU_KHIEN!$B$6)) -> 0.5 | J7: 0.4 | K7: =IF(B7="","",IF(J7="",I7,J7)) -> 0.4 | L7: =IF(OR(F7="",G7=0),"",MIN(1,F7/G7)) -> 1 | M7: =IF(B7="","",H7*K7*L7) -> 1944000 | P7: =IF(B7="","",MAX(0,M7+N7-O7)) -> 1944000
A8: =IFERROR(PHAN_CONG!$A$8,"") | B8: =IFERROR(PHAN_CONG!$B$8,"") | C8: =IFERROR(PHAN_CONG!$C$8,"") | D8: =IFERROR(PHAN_CONG!$D$8,"") | E8: =IFERROR(PHAN_CONG!$E$8,"") | F8: =IFERROR(PHAN_CONG!$F$8,"") | G8: =IF(D8="","",SUMIF(TONG_HOP_LOP!$B$4:$B$15,D8,TONG_HOP_LOP!$E$4:$E$15)) | H8: =IF(D8="","",SUMIF(TONG_HOP_LOP!$B$4:$B$15,D8,TONG_HOP_LOP!$G$4:$G$15)) | I8: =IF(D8="","",IFERROR(VLOOKUP(D8,DANH_MUC_LOP!$B$4:$O$15,14,FALSE),DIEU_KHIEN!$B$6)) | K8: =IF(B8="","",IF(J8="",I8,J8)) | L8: =IF(OR(F8="",G8=0),"",MIN(1,F8/G8)) | M8: =IF(B8="","",H8*K8*L8) | P8: =IF(B8="","",MAX(0,M8+N8-O8))
A9: =IFERROR(PHAN_CONG!$A$9,"") | B9: =IFERROR(PHAN_CONG!$B$9,"") | C9: =IFERROR(PHAN_CONG!$C$9,"") | D9: =IFERROR(PHAN_CONG!$D$9,"") | E9: =IFERROR(PHAN_CONG!$E$9,"") | F9: =IFERROR(PHAN_CONG!$F$9,"") | G9: =IF(D9="","",SUMIF(TONG_HOP_LOP!$B$4:$B$15,D9,TONG_HOP_LOP!$E$4:$E$15)) | H9: =IF(D9="","",SUMIF(TONG_HOP_LOP!$B$4:$B$15,D9,TONG_HOP_LOP!$G$4:$G$15)) | I9: =IF(D9="","",IFERROR(VLOOKUP(D9,DANH_MUC_LOP!$B$4:$O$15,14,FALSE),DIEU_KHIEN!$B$6)) | K9: =IF(B9="","",IF(J9="",I9,J9)) | L9: =IF(OR(F9="",G9=0),"",MIN(1,F9/G9)) | M9: =IF(B9="","",H9*K9*L9) | P9: =IF(B9="","",MAX(0,M9+N9-O9))
A10: =IFERROR(PHAN_CONG!$A$10,"") | B10: =IFERROR(PHAN_CONG!$B$10,"") | C10: =IFERROR(PHAN_CONG!$C$10,"") | D10: =IFERROR(PHAN_CONG!$D$10,"") | E10: =IFERROR(PHAN_CONG!$E$10,"") | F10: =IFERROR(PHAN_CONG!$F$10,"") | G10: =IF(D10="","",SUMIF(TONG_HOP_LOP!$B$4:$B$15,D10,TONG_HOP_LOP!$E$4:$E$15)) | H10: =IF(D10="","",SUMIF(TONG_HOP_LOP!$B$4:$B$15,D10,TONG_HOP_LOP!$G$4:$G$15)) | I10: =IF(D10="","",IFERROR(VLOOKUP(D10,DANH_MUC_LOP!$B$4:$O$15,14,FALSE),DIEU_KHIEN!$B$6)) | K10: =IF(B10="","",IF(J10="",I10,J10)) | L10: =IF(OR(F10="",G10=0),"",MIN(1,F10/G10)) | M10: =IF(B10="","",H10*K10*L10) | P10: =IF(B10="","",MAX(0,M10+N10-O10))
A11: =IFERROR(PHAN_CONG!$A$11,"") | B11: =IFERROR(PHAN_CONG!$B$11,"") | C11: =IFERROR(PHAN_CONG!$C$11,"") | D11: =IFERROR(PHAN_CONG!$D$11,"") | E11: =IFERROR(PHAN_CONG!$E$11,"") | F11: =IFERROR(PHAN_CONG!$F$11,"") | G11: =IF(D11="","",SUMIF(TONG_HOP_LOP!$B$4:$B$15,D11,TONG_HOP_LOP!$E$4:$E$15)) | H11: =IF(D11="","",SUMIF(TONG_HOP_LOP!$B$4:$B$15,D11,TONG_HOP_LOP!$G$4:$G$15)) | I11: =IF(D11="","",IFERROR(VLOOKUP(D11,DANH_MUC_LOP!$B$4:$O$15,14,FALSE),DIEU_KHIEN!$B$6)) | K11: =IF(B11="","",IF(J11="",I11,J11)) | L11: =IF(OR(F11="",G11=0),"",MIN(1,F11/G11)) | M11: =IF(B11="","",H11*K11*L11) | P11: =IF(B11="","",MAX(0,M11+N11-O11))
A12: =IFERROR(PHAN_CONG!$A$12,"") | B12: =IFERROR(PHAN_CONG!$B$12,"") | C12: =IFERROR(PHAN_CONG!$C$12,"") | D12: =IFERROR(PHAN_CONG!$D$12,"") | E12: =IFERROR(PHAN_CONG!$E$12,"") | F12: =IFERROR(PHAN_CONG!$F$12,"") | G12: =IF(D12="","",SUMIF(TONG_HOP_LOP!$B$4:$B$15,D12,TONG_HOP_LOP!$E$4:$E$15)) | H12: =IF(D12="","",SUMIF(TONG_HOP_LOP!$B$4:$B$15,D12,TONG_HOP_LOP!$G$4:$G$15)) | I12: =IF(D12="","",IFERROR(VLOOKUP(D12,DANH_MUC_LOP!$B$4:$O$15,14,FALSE),DIEU_KHIEN!$B$6)) | K12: =IF(B12="","",IF(J12="",I12,J12)) | L12: =IF(OR(F12="",G12=0),"",MIN(1,F12/G12)) | M12: =IF(B12="","",H12*K12*L12) | P12: =IF(B12="","",MAX(0,M12+N12-O12))
A13: =IFERROR(PHAN_CONG!$A$13,"") | B13: =IFERROR(PHAN_CONG!$B$13,"") | C13: =IFERROR(PHAN_CONG!$C$13,"") | D13: =IFERROR(PHAN_CONG!$D$13,"") | E13: =IFERROR(PHAN_CONG!$E$13,"") | F13: =IFERROR(PHAN_CONG!$F$13,"") | G13: =IF(D13="","",SUMIF(TONG_HOP_LOP!$B$4:$B$15,D13,TONG_HOP_LOP!$E$4:$E$15)) | H13: =IF(D13="","",SUMIF(TONG_HOP_LOP!$B$4:$B$15,D13,TONG_HOP_LOP!$G$4:$G$15)) | I13: =IF(D13="","",IFERROR(VLOOKUP(D13,DANH_MUC_LOP!$B$4:$O$15,14,FALSE),DIEU_KHIEN!$B$6)) | K13: =IF(B13="","",IF(J13="",I13,J13)) | L13: =IF(OR(F13="",G13=0),"",MIN(1,F13/G13)) | M13: =IF(B13="","",H13*K13*L13) | P13: =IF(B13="","",MAX(0,M13+N13-O13))
A14: =IFERROR(PHAN_CONG!$A$14,"") | B14: =IFERROR(PHAN_CONG!$B$14,"") | C14: =IFERROR(PHAN_CONG!$C$14,"") | D14: =IFERROR(PHAN_CONG!$D$14,"") | E14: =IFERROR(PHAN_CONG!$E$14,"") | F14: =IFERROR(PHAN_CONG!$F$14,"") | G14: =IF(D14="","",SUMIF(TONG_HOP_LOP!$B$4:$B$15,D14,TONG_HOP_LOP!$E$4:$E$15)) | H14: =IF(D14="","",SUMIF(TONG_HOP_LOP!$B$4:$B$15,D14,TONG_HOP_LOP!$G$4:$G$15)) | I14: =IF(D14="","",IFERROR(VLOOKUP(D14,DANH_MUC_LOP!$B$4:$O$15,14,FALSE),DIEU_KHIEN!$B$6)) | K14: =IF(B14="","",IF(J14="",I14,J14)) | L14: =IF(OR(F14="",G14=0),"",MIN(1,F14/G14)) | M14: =IF(B14="","",H14*K14*L14) | P14: =IF(B14="","",MAX(0,M14+N14-O14))
A15: =IFERROR(PHAN_CONG!$A$15,"") | B15: =IFERROR(PHAN_CONG!$B$15,"") | C15: =IFERROR(PHAN_CONG!$C$15,"") | D15: =IFERROR(PHAN_CONG!$D$15,"") | E15: =IFERROR(PHAN_CONG!$E$15,"") | F15: =IFERROR(PHAN_CONG!$F$15,"") | G15: =IF(D15="","",SUMIF(TONG_HOP_LOP!$B$4:$B$15,D15,TONG_HOP_LOP!$E$4:$E$15)) | H15: =IF(D15="","",SUMIF(TONG_HOP_LOP!$B$4:$B$15,D15,TONG_HOP_LOP!$G$4:$G$15)) | I15: =IF(D15="","",IFERROR(VLOOKUP(D15,DANH_MUC_LOP!$B$4:$O$15,14,FALSE),DIEU_KHIEN!$B$6)) | K15: =IF(B15="","",IF(J15="",I15,J15)) | L15: =IF(OR(F15="",G15=0),"",MIN(1,F15/G15)) | M15: =IF(B15="","",H15*K15*L15) | P15: =IF(B15="","",MAX(0,M15+N15-O15))
A16: =IFERROR(PHAN_CONG!$A$16,"") | B16: =IFERROR(PHAN_CONG!$B$16,"") | C16: =IFERROR(PHAN_CONG!$C$16,"") | D16: =IFERROR(PHAN_CONG!$D$16,"") | E16: =IFERROR(PHAN_CONG!$E$16,"") | F16: =IFERROR(PHAN_CONG!$F$16,"") | G16: =IF(D16="","",SUMIF(TONG_HOP_LOP!$B$4:$B$15,D16,TONG_HOP_LOP!$E$4:$E$15)) | H16: =IF(D16="","",SUMIF(TONG_HOP_LOP!$B$4:$B$15,D16,TONG_HOP_LOP!$G$4:$G$15)) | I16: =IF(D16="","",IFERROR(VLOOKUP(D16,DANH_MUC_LOP!$B$4:$O$15,14,FALSE),DIEU_KHIEN!$B$6)) | K16: =IF(B16="","",IF(J16="",I16,J16)) | L16: =IF(OR(F16="",G16=0),"",MIN(1,F16/G16)) | M16: =IF(B16="","",H16*K16*L16) | P16: =IF(B16="","",MAX(0,M16+N16-O16))
A17: =IFERROR(PHAN_CONG!$A$17,"") | B17: =IFERROR(PHAN_CONG!$B$17,"") | C17: =IFERROR(PHAN_CONG!$C$17,"") | D17: =IFERROR(PHAN_CONG!$D$17,"") | E17: =IFERROR(PHAN_CONG!$E$17,"") | F17: =IFERROR(PHAN_CONG!$F$17,"") | G17: =IF(D17="","",SUMIF(TONG_HOP_LOP!$B$4:$B$15,D17,TONG_HOP_LOP!$E$4:$E$15)) | H17: =IF(D17="","",SUMIF(TONG_HOP_LOP!$B$4:$B$15,D17,TONG_HOP_LOP!$G$4:$G$15)) | I17: =IF(D17="","",IFERROR(VLOOKUP(D17,DANH_MUC_LOP!$B$4:$O$15,14,FALSE),DIEU_KHIEN!$B$6)) | K17: =IF(B17="","",IF(J17="",I17,J17)) | L17: =IF(OR(F17="",G17=0),"",MIN(1,F17/G17)) | M17: =IF(B17="","",H17*K17*L17) | P17: =IF(B17="","",MAX(0,M17+N17-O17))
A18: =IFERROR(PHAN_CONG!$A$18,"") | B18: =IFERROR(PHAN_CONG!$B$18,"") | C18: =IFERROR(PHAN_CONG!$C$18,"") | D18: =IFERROR(PHAN_CONG!$D$18,"") | E18: =IFERROR(PHAN_CONG!$E$18,"") | F18: =IFERROR(PHAN_CONG!$F$18,"") | G18: =IF(D18="","",SUMIF(TONG_HOP_LOP!$B$4:$B$15,D18,TONG_HOP_LOP!$E$4:$E$15)) | H18: =IF(D18="","",SUMIF(TONG_HOP_LOP!$B$4:$B$15,D18,TONG_HOP_LOP!$G$4:$G$15)) | I18: =IF(D18="","",IFERROR(VLOOKUP(D18,DANH_MUC_LOP!$B$4:$O$15,14,FALSE),DIEU_KHIEN!$B$6)) | K18: =IF(B18="","",IF(J18="",I18,J18)) | L18: =IF(OR(F18="",G18=0),"",MIN(1,F18/G18)) | M18: =IF(B18="","",H18*K18*L18) | P18: =IF(B18="","",MAX(0,M18+N18-O18))
A19: =IFERROR(PHAN_CONG!$A$19,"") | B19: =IFERROR(PHAN_CONG!$B$19,"") | C19: =IFERROR(PHAN_CONG!$C$19,"") | D19: =IFERROR(PHAN_CONG!$D$19,"") | E19: =IFERROR(PHAN_CONG!$E$19,"") | F19: =IFERROR(PHAN_CONG!$F$19,"") | G19: =IF(D19="","",SUMIF(TONG_HOP_LOP!$B$4:$B$15,D19,TONG_HOP_LOP!$E$4:$E$15)) | H19: =IF(D19="","",SUMIF(TONG_HOP_LOP!$B$4:$B$15,D19,TONG_HOP_LOP!$G$4:$G$15)) | I19: =IF(D19="","",IFERROR(VLOOKUP(D19,DANH_MUC_LOP!$B$4:$O$15,14,FALSE),DIEU_KHIEN!$B$6)) | K19: =IF(B19="","",IF(J19="",I19,J19)) | L19: =IF(OR(F19="",G19=0),"",MIN(1,F19/G19)) | M19: =IF(B19="","",H19*K19*L19) | P19: =IF(B19="","",MAX(0,M19+N19-O19))
A20: =IFERROR(PHAN_CONG!$A$20,"") | B20: =IFERROR(PHAN_CONG!$B$20,"") | C20: =IFERROR(PHAN_CONG!$C$20,"") | D20: =IFERROR(PHAN_CONG!$D$20,"") | E20: =IFERROR(PHAN_CONG!$E$20,"") | F20: =IFERROR(PHAN_CONG!$F$20,"") | G20: =IF(D20="","",SUMIF(TONG_HOP_LOP!$B$4:$B$15,D20,TONG_HOP_LOP!$E$4:$E$15)) | H20: =IF(D20="","",SUMIF(TONG_HOP_LOP!$B$4:$B$15,D20,TONG_HOP_LOP!$G$4:$G$15)) | I20: =IF(D20="","",IFERROR(VLOOKUP(D20,DANH_MUC_LOP!$B$4:$O$15,14,FALSE),DIEU_KHIEN!$B$6)) | K20: =IF(B20="","",IF(J20="",I20,J20)) | L20: =IF(OR(F20="",G20=0),"",MIN(1,F20/G20)) | M20: =IF(B20="","",H20*K20*L20) | P20: =IF(B20="","",MAX(0,M20+N20-O20))
A21: =IFERROR(PHAN_CONG!$A$21,"") | B21: =IFERROR(PHAN_CONG!$B$21,"") | C21: =IFERROR(PHAN_CONG!$C$21,"") | D21: =IFERROR(PHAN_CONG!$D$21,"") | E21: =IFERROR(PHAN_CONG!$E$21,"") | F21: =IFERROR(PHAN_CONG!$F$21,"") | G21: =IF(D21="","",SUMIF(TONG_HOP_LOP!$B$4:$B$15,D21,TONG_HOP_LOP!$E$4:$E$15)) | H21: =IF(D21="","",SUMIF(TONG_HOP_LOP!$B$4:$B$15,D21,TONG_HOP_LOP!$G$4:$G$15)) | I21: =IF(D21="","",IFERROR(VLOOKUP(D21,DANH_MUC_LOP!$B$4:$O$15,14,FALSE),DIEU_KHIEN!$B$6)) | K21: =IF(B21="","",IF(J21="",I21,J21)) | L21: =IF(OR(F21="",G21=0),"",MIN(1,F21/G21)) | M21: =IF(B21="","",H21*K21*L21) | P21: =IF(B21="","",MAX(0,M21+N21-O21))
A22: =IFERROR(PHAN_CONG!$A$22,"") | B22: =IFERROR(PHAN_CONG!$B$22,"") | C22: =IFERROR(PHAN_CONG!$C$22,"") | D22: =IFERROR(PHAN_CONG!$D$22,"") | E22: =IFERROR(PHAN_CONG!$E$22,"") | F22: =IFERROR(PHAN_CONG!$F$22,"") | G22: =IF(D22="","",SUMIF(TONG_HOP_LOP!$B$4:$B$15,D22,TONG_HOP_LOP!$E$4:$E$15)) | H22: =IF(D22="","",SUMIF(TONG_HOP_LOP!$B$4:$B$15,D22,TONG_HOP_LOP!$G$4:$G$15)) | I22: =IF(D22="","",IFERROR(VLOOKUP(D22,DANH_MUC_LOP!$B$4:$O$15,14,FALSE),DIEU_KHIEN!$B$6)) | K22: =IF(B22="","",IF(J22="",I22,J22)) | L22: =IF(OR(F22="",G22=0),"",MIN(1,F22/G22)) | M22: =IF(B22="","",H22*K22*L22) | P22: =IF(B22="","",MAX(0,M22+N22-O22))
A23: =IFERROR(PHAN_CONG!$A$23,"") | B23: =IFERROR(PHAN_CONG!$B$23,"") | C23: =IFERROR(PHAN_CONG!$C$23,"") | D23: =IFERROR(PHAN_CONG!$D$23,"") | E23: =IFERROR(PHAN_CONG!$E$23,"") | F23: =IFERROR(PHAN_CONG!$F$23,"") | G23: =IF(D23="","",SUMIF(TONG_HOP_LOP!$B$4:$B$15,D23,TONG_HOP_LOP!$E$4:$E$15)) | H23: =IF(D23="","",SUMIF(TONG_HOP_LOP!$B$4:$B$15,D23,TONG_HOP_LOP!$G$4:$G$15)) | I23: =IF(D23="","",IFERROR(VLOOKUP(D23,DANH_MUC_LOP!$B$4:$O$15,14,FALSE),DIEU_KHIEN!$B$6)) | K23: =IF(B23="","",IF(J23="",I23,J23)) | L23: =IF(OR(F23="",G23=0),"",MIN(1,F23/G23)) | M23: =IF(B23="","",H23*K23*L23) | P23: =IF(B23="","",MAX(0,M23+N23-O23))
A24: =IFERROR(PHAN_CONG!$A$24,"") | B24: =IFERROR(PHAN_CONG!$B$24,"") | C24: =IFERROR(PHAN_CONG!$C$24,"") | D24: =IFERROR(PHAN_CONG!$D$24,"") | E24: =IFERROR(PHAN_CONG!$E$24,"") | F24: =IFERROR(PHAN_CONG!$F$24,"") | G24: =IF(D24="","",SUMIF(TONG_HOP_LOP!$B$4:$B$15,D24,TONG_HOP_LOP!$E$4:$E$15)) | H24: =IF(D24="","",SUMIF(TONG_HOP_LOP!$B$4:$B$15,D24,TONG_HOP_LOP!$G$4:$G$15)) | I24: =IF(D24="","",IFERROR(VLOOKUP(D24,DANH_MUC_LOP!$B$4:$O$15,14,FALSE),DIEU_KHIEN!$B$6)) | K24: =IF(B24="","",IF(J24="",I24,J24)) | L24: =IF(OR(F24="",G24=0),"",MIN(1,F24/G24)) | M24: =IF(B24="","",H24*K24*L24) | P24: =IF(B24="","",MAX(0,M24+N24-O24))
A25: =IFERROR(PHAN_CONG!$A$25,"") | B25: =IFERROR(PHAN_CONG!$B$25,"") | C25: =IFERROR(PHAN_CONG!$C$25,"") | D25: =IFERROR(PHAN_CONG!$D$25,"") | E25: =IFERROR(PHAN_CONG!$E$25,"") | F25: =IFERROR(PHAN_CONG!$F$25,"") | G25: =IF(D25="","",SUMIF(TONG_HOP_LOP!$B$4:$B$15,D25,TONG_HOP_LOP!$E$4:$E$15)) | H25: =IF(D25="","",SUMIF(TONG_HOP_LOP!$B$4:$B$15,D25,TONG_HOP_LOP!$G$4:$G$15)) | I25: =IF(D25="","",IFERROR(VLOOKUP(D25,DANH_MUC_LOP!$B$4:$O$15,14,FALSE),DIEU_KHIEN!$B$6)) | K25: =IF(B25="","",IF(J25="",I25,J25)) | L25: =IF(OR(F25="",G25=0),"",MIN(1,F25/G25)) | M25: =IF(B25="","",H25*K25*L25) | P25: =IF(B25="","",MAX(0,M25+N25-O25))
A26: =IFERROR(PHAN_CONG!$A$26,"") | B26: =IFERROR(PHAN_CONG!$B$26,"") | C26: =IFERROR(PHAN_CONG!$C$26,"") | D26: =IFERROR(PHAN_CONG!$D$26,"") | E26: =IFERROR(PHAN_CONG!$E$26,"") | F26: =IFERROR(PHAN_CONG!$F$26,"") | G26: =IF(D26="","",SUMIF(TONG_HOP_LOP!$B$4:$B$15,D26,TONG_HOP_LOP!$E$4:$E$15)) | H26: =IF(D26="","",SUMIF(TONG_HOP_LOP!$B$4:$B$15,D26,TONG_HOP_LOP!$G$4:$G$15)) | I26: =IF(D26="","",IFERROR(VLOOKUP(D26,DANH_MUC_LOP!$B$4:$O$15,14,FALSE),DIEU_KHIEN!$B$6)) | K26: =IF(B26="","",IF(J26="",I26,J26)) | L26: =IF(OR(F26="",G26=0),"",MIN(1,F26/G26)) | M26: =IF(B26="","",H26*K26*L26) | P26: =IF(B26="","",MAX(0,M26+N26-O26))
A27: =IFERROR(PHAN_CONG!$A$27,"") | B27: =IFERROR(PHAN_CONG!$B$27,"") | C27: =IFERROR(PHAN_CONG!$C$27,"") | D27: =IFERROR(PHAN_CONG!$D$27,"") | E27: =IFERROR(PHAN_CONG!$E$27,"") | F27: =IFERROR(PHAN_CONG!$F$27,"") | G27: =IF(D27="","",SUMIF(TONG_HOP_LOP!$B$4:$B$15,D27,TONG_HOP_LOP!$E$4:$E$15)) | H27: =IF(D27="","",SUMIF(TONG_HOP_LOP!$B$4:$B$15,D27,TONG_HOP_LOP!$G$4:$G$15)) | I27: =IF(D27="","",IFERROR(VLOOKUP(D27,DANH_MUC_LOP!$B$4:$O$15,14,FALSE),DIEU_KHIEN!$B$6)) | K27: =IF(B27="","",IF(J27="",I27,J27)) | L27: =IF(OR(F27="",G27=0),"",MIN(1,F27/G27)) | M27: =IF(B27="","",H27*K27*L27) | P27: =IF(B27="","",MAX(0,M27+N27-O27))
A28: =IFERROR(PHAN_CONG!$A$28,"") | B28: =IFERROR(PHAN_CONG!$B$28,"") | C28: =IFERROR(PHAN_CONG!$C$28,"") | D28: =IFERROR(PHAN_CONG!$D$28,"") | E28: =IFERROR(PHAN_CONG!$E$28,"") | F28: =IFERROR(PHAN_CONG!$F$28,"") | G28: =IF(D28="","",SUMIF(TONG_HOP_LOP!$B$4:$B$15,D28,TONG_HOP_LOP!$E$4:$E$15)) | H28: =IF(D28="","",SUMIF(TONG_HOP_LOP!$B$4:$B$15,D28,TONG_HOP_LOP!$G$4:$G$15)) | I28: =IF(D28="","",IFERROR(VLOOKUP(D28,DANH_MUC_LOP!$B$4:$O$15,14,FALSE),DIEU_KHIEN!$B$6)) | K28: =IF(B28="","",IF(J28="",I28,J28)) | L28: =IF(OR(F28="",G28=0),"",MIN(1,F28/G28)) | M28: =IF(B28="","",H28*K28*L28) | P28: =IF(B28="","",MAX(0,M28+N28-O28))
A29: =IFERROR(PHAN_CONG!$A$29,"") | B29: =IFERROR(PHAN_CONG!$B$29,"") | C29: =IFERROR(PHAN_CONG!$C$29,"") | D29: =IFERROR(PHAN_CONG!$D$29,"") | E29: =IFERROR(PHAN_CONG!$E$29,"") | F29: =IFERROR(PHAN_CONG!$F$29,"") | G29: =IF(D29="","",SUMIF(TONG_HOP_LOP!$B$4:$B$15,D29,TONG_HOP_LOP!$E$4:$E$15)) | H29: =IF(D29="","",SUMIF(TONG_HOP_LOP!$B$4:$B$15,D29,TONG_HOP_LOP!$G$4:$G$15)) | I29: =IF(D29="","",IFERROR(VLOOKUP(D29,DANH_MUC_LOP!$B$4:$O$15,14,FALSE),DIEU_KHIEN!$B$6)) | K29: =IF(B29="","",IF(J29="",I29,J29)) | L29: =IF(OR(F29="",G29=0),"",MIN(1,F29/G29)) | M29: =IF(B29="","",H29*K29*L29) | P29: =IF(B29="","",MAX(0,M29+N29-O29))
A30: =IFERROR(PHAN_CONG!$A$30,"") | B30: =IFERROR(PHAN_CONG!$B$30,"") | C30: =IFERROR(PHAN_CONG!$C$30,"") | D30: =IFERROR(PHAN_CONG!$D$30,"") | E30: =IFERROR(PHAN_CONG!$E$30,"") | F30: =IFERROR(PHAN_CONG!$F$30,"") | G30: =IF(D30="","",SUMIF(TONG_HOP_LOP!$B$4:$B$15,D30,TONG_HOP_LOP!$E$4:$E$15)) | H30: =IF(D30="","",SUMIF(TONG_HOP_LOP!$B$4:$B$15,D30,TONG_HOP_LOP!$G$4:$G$15)) | I30: =IF(D30="","",IFERROR(VLOOKUP(D30,DANH_MUC_LOP!$B$4:$O$15,14,FALSE),DIEU_KHIEN!$B$6)) | K30: =IF(B30="","",IF(J30="",I30,J30)) | L30: =IF(OR(F30="",G30=0),"",MIN(1,F30/G30)) | M30: =IF(B30="","",H30*K30*L30) | P30: =IF(B30="","",MAX(0,M30+N30-O30))
A31: =IFERROR(PHAN_CONG!$A$31,"") | B31: =IFERROR(PHAN_CONG!$B$31,"") | C31: =IFERROR(PHAN_CONG!$C$31,"") | D31: =IFERROR(PHAN_CONG!$D$31,"") | E31: =IFERROR(PHAN_CONG!$E$31,"") | F31: =IFERROR(PHAN_CONG!$F$31,"") | G31: =IF(D31="","",SUMIF(TONG_HOP_LOP!$B$4:$B$15,D31,TONG_HOP_LOP!$E$4:$E$15)) | H31: =IF(D31="","",SUMIF(TONG_HOP_LOP!$B$4:$B$15,D31,TONG_HOP_LOP!$G$4:$G$15)) | I31: =IF(D31="","",IFERROR(VLOOKUP(D31,DANH_MUC_LOP!$B$4:$O$15,14,FALSE),DIEU_KHIEN!$B$6)) | K31: =IF(B31="","",IF(J31="",I31,J31)) | L31: =IF(OR(F31="",G31=0),"",MIN(1,F31/G31)) | M31: =IF(B31="","",H31*K31*L31) | P31: =IF(B31="","",MAX(0,M31+N31-O31))
A32: =IFERROR(PHAN_CONG!$A$32,"") | B32: =IFERROR(PHAN_CONG!$B$32,"") | C32: =IFERROR(PHAN_CONG!$C$32,"") | D32: =IFERROR(PHAN_CONG!$D$32,"") | E32: =IFERROR(PHAN_CONG!$E$32,"") | F32: =IFERROR(PHAN_CONG!$F$32,"") | G32: =IF(D32="","",SUMIF(TONG_HOP_LOP!$B$4:$B$15,D32,TONG_HOP_LOP!$E$4:$E$15)) | H32: =IF(D32="","",SUMIF(TONG_HOP_LOP!$B$4:$B$15,D32,TONG_HOP_LOP!$G$4:$G$15)) | I32: =IF(D32="","",IFERROR(VLOOKUP(D32,DANH_MUC_LOP!$B$4:$O$15,14,FALSE),DIEU_KHIEN!$B$6)) | K32: =IF(B32="","",IF(J32="",I32,J32)) | L32: =IF(OR(F32="",G32=0),"",MIN(1,F32/G32)) | M32: =IF(B32="","",H32*K32*L32) | P32: =IF(B32="","",MAX(0,M32+N32-O32))
A33: =IFERROR(PHAN_CONG!$A$33,"") | B33: =IFERROR(PHAN_CONG!$B$33,"") | C33: =IFERROR(PHAN_CONG!$C$33,"") | D33: =IFERROR(PHAN_CONG!$D$33,"") | E33: =IFERROR(PHAN_CONG!$E$33,"") | F33: =IFERROR(PHAN_CONG!$F$33,"") | G33: =IF(D33="","",SUMIF(TONG_HOP_LOP!$B$4:$B$15,D33,TONG_HOP_LOP!$E$4:$E$15)) | H33: =IF(D33="","",SUMIF(TONG_HOP_LOP!$B$4:$B$15,D33,TONG_HOP_LOP!$G$4:$G$15)) | I33: =IF(D33="","",IFERROR(VLOOKUP(D33,DANH_MUC_LOP!$B$4:$O$15,14,FALSE),DIEU_KHIEN!$B$6)) | K33: =IF(B33="","",IF(J33="",I33,J33)) | L33: =IF(OR(F33="",G33=0),"",MIN(1,F33/G33)) | M33: =IF(B33="","",H33*K33*L33) | P33: =IF(B33="","",MAX(0,M33+N33-O33))
A34: =IFERROR(PHAN_CONG!$A$34,"") | B34: =IFERROR(PHAN_CONG!$B$34,"") | C34: =IFERROR(PHAN_CONG!$C$34,"") | D34: =IFERROR(PHAN_CONG!$D$34,"") | E34: =IFERROR(PHAN_CONG!$E$34,"") | F34: =IFERROR(PHAN_CONG!$F$34,"") | G34: =IF(D34="","",SUMIF(TONG_HOP_LOP!$B$4:$B$15,D34,TONG_HOP_LOP!$E$4:$E$15)) | H34: =IF(D34="","",SUMIF(TONG_HOP_LOP!$B$4:$B$15,D34,TONG_HOP_LOP!$G$4:$G$15)) | I34: =IF(D34="","",IFERROR(VLOOKUP(D34,DANH_MUC_LOP!$B$4:$O$15,14,FALSE),DIEU_KHIEN!$B$6)) | K34: =IF(B34="","",IF(J34="",I34,J34)) | L34: =IF(OR(F34="",G34=0),"",MIN(1,F34/G34)) | M34: =IF(B34="","",H34*K34*L34) | P34: =IF(B34="","",MAX(0,M34+N34-O34))
A35: =IFERROR(PHAN_CONG!$A$35,"") | B35: =IFERROR(PHAN_CONG!$B$35,"") | C35: =IFERROR(PHAN_CONG!$C$35,"") | D35: =IFERROR(PHAN_CONG!$D$35,"") | E35: =IFERROR(PHAN_CONG!$E$35,"") | F35: =IFERROR(PHAN_CONG!$F$35,"") | G35: =IF(D35="","",SUMIF(TONG_HOP_LOP!$B$4:$B$15,D35,TONG_HOP_LOP!$E$4:$E$15)) | H35: =IF(D35="","",SUMIF(TONG_HOP_LOP!$B$4:$B$15,D35,TONG_HOP_LOP!$G$4:$G$15)) | I35: =IF(D35="","",IFERROR(VLOOKUP(D35,DANH_MUC_LOP!$B$4:$O$15,14,FALSE),DIEU_KHIEN!$B$6)) | K35: =IF(B35="","",IF(J35="",I35,J35)) | L35: =IF(OR(F35="",G35=0),"",MIN(1,F35/G35)) | M35: =IF(B35="","",H35*K35*L35) | P35: =IF(B35="","",MAX(0,M35+N35-O35))
A36: =IFERROR(PHAN_CONG!$A$36,"") | B36: =IFERROR(PHAN_CONG!$B$36,"") | C36: =IFERROR(PHAN_CONG!$C$36,"") | D36: =IFERROR(PHAN_CONG!$D$36,"") | E36: =IFERROR(PHAN_CONG!$E$36,"") | F36: =IFERROR(PHAN_CONG!$F$36,"") | G36: =IF(D36="","",SUMIF(TONG_HOP_LOP!$B$4:$B$15,D36,TONG_HOP_LOP!$E$4:$E$15)) | H36: =IF(D36="","",SUMIF(TONG_HOP_LOP!$B$4:$B$15,D36,TONG_HOP_LOP!$G$4:$G$15)) | I36: =IF(D36="","",IFERROR(VLOOKUP(D36,DANH_MUC_LOP!$B$4:$O$15,14,FALSE),DIEU_KHIEN!$B$6)) | K36: =IF(B36="","",IF(J36="",I36,J36)) | L36: =IF(OR(F36="",G36=0),"",MIN(1,F36/G36)) | M36: =IF(B36="","",H36*K36*L36) | P36: =IF(B36="","",MAX(0,M36+N36-O36))
A37: =IFERROR(PHAN_CONG!$A$37,"") | B37: =IFERROR(PHAN_CONG!$B$37,"") | C37: =IFERROR(PHAN_CONG!$C$37,"") | D37: =IFERROR(PHAN_CONG!$D$37,"") | E37: =IFERROR(PHAN_CONG!$E$37,"") | F37: =IFERROR(PHAN_CONG!$F$37,"") | G37: =IF(D37="","",SUMIF(TONG_HOP_LOP!$B$4:$B$15,D37,TONG_HOP_LOP!$E$4:$E$15)) | H37: =IF(D37="","",SUMIF(TONG_HOP_LOP!$B$4:$B$15,D37,TONG_HOP_LOP!$G$4:$G$15)) | I37: =IF(D37="","",IFERROR(VLOOKUP(D37,DANH_MUC_LOP!$B$4:$O$15,14,FALSE),DIEU_KHIEN!$B$6)) | K37: =IF(B37="","",IF(J37="",I37,J37)) | L37: =IF(OR(F37="",G37=0),"",MIN(1,F37/G37)) | M37: =IF(B37="","",H37*K37*L37) | P37: =IF(B37="","",MAX(0,M37+N37-O37))
A38: =IFERROR(PHAN_CONG!$A$38,"") | B38: =IFERROR(PHAN_CONG!$B$38,"") | C38: =IFERROR(PHAN_CONG!$C$38,"") | D38: =IFERROR(PHAN_CONG!$D$38,"") | E38: =IFERROR(PHAN_CONG!$E$38,"") | F38: =IFERROR(PHAN_CONG!$F$38,"") | G38: =IF(D38="","",SUMIF(TONG_HOP_LOP!$B$4:$B$15,D38,TONG_HOP_LOP!$E$4:$E$15)) | H38: =IF(D38="","",SUMIF(TONG_HOP_LOP!$B$4:$B$15,D38,TONG_HOP_LOP!$G$4:$G$15)) | I38: =IF(D38="","",IFERROR(VLOOKUP(D38,DANH_MUC_LOP!$B$4:$O$15,14,FALSE),DIEU_KHIEN!$B$6)) | K38: =IF(B38="","",IF(J38="",I38,J38)) | L38: =IF(OR(F38="",G38=0),"",MIN(1,F38/G38)) | M38: =IF(B38="","",H38*K38*L38) | P38: =IF(B38="","",MAX(0,M38+N38-O38))
A39: =IFERROR(PHAN_CONG!$A$39,"") | B39: =IFERROR(PHAN_CONG!$B$39,"") | C39: =IFERROR(PHAN_CONG!$C$39,"") | D39: =IFERROR(PHAN_CONG!$D$39,"") | E39: =IFERROR(PHAN_CONG!$E$39,"") | F39: =IFERROR(PHAN_CONG!$F$39,"") | G39: =IF(D39="","",SUMIF(TONG_HOP_LOP!$B$4:$B$15,D39,TONG_HOP_LOP!$E$4:$E$15)) | H39: =IF(D39="","",SUMIF(TONG_HOP_LOP!$B$4:$B$15,D39,TONG_HOP_LOP!$G$4:$G$15)) | I39: =IF(D39="","",IFERROR(VLOOKUP(D39,DANH_MUC_LOP!$B$4:$O$15,14,FALSE),DIEU_KHIEN!$B$6)) | K39: =IF(B39="","",IF(J39="",I39,J39)) | L39: =IF(OR(F39="",G39=0),"",MIN(1,F39/G39)) | M39: =IF(B39="","",H39*K39*L39) | P39: =IF(B39="","",MAX(0,M39+N39-O39))
A40: =IFERROR(PHAN_CONG!$A$40,"") | B40: =IFERROR(PHAN_CONG!$B$40,"") | C40: =IFERROR(PHAN_CONG!$C$40,"") | D40: =IFERROR(PHAN_CONG!$D$40,"") | E40: =IFERROR(PHAN_CONG!$E$40,"") | F40: =IFERROR(PHAN_CONG!$F$40,"") | G40: =IF(D40="","",SUMIF(TONG_HOP_LOP!$B$4:$B$15,D40,TONG_HOP_LOP!$E$4:$E$15)) | H40: =IF(D40="","",SUMIF(TONG_HOP_LOP!$B$4:$B$15,D40,TONG_HOP_LOP!$G$4:$G$15)) | I40: =IF(D40="","",IFERROR(VLOOKUP(D40,DANH_MUC_LOP!$B$4:$O$15,14,FALSE),DIEU_KHIEN!$B$6)) | K40: =IF(B40="","",IF(J40="",I40,J40)) | L40: =IF(OR(F40="",G40=0),"",MIN(1,F40/G40)) | M40: =IF(B40="","",H40*K40*L40) | P40: =IF(B40="","",MAX(0,M40+N40-O40))
A41: =IFERROR(PHAN_CONG!$A$41,"") | B41: =IFERROR(PHAN_CONG!$B$41,"") | C41: =IFERROR(PHAN_CONG!$C$41,"") | D41: =IFERROR(PHAN_CONG!$D$41,"") | E41: =IFERROR(PHAN_CONG!$E$41,"") | F41: =IFERROR(PHAN_CONG!$F$41,"") | G41: =IF(D41="","",SUMIF(TONG_HOP_LOP!$B$4:$B$15,D41,TONG_HOP_LOP!$E$4:$E$15)) | H41: =IF(D41="","",SUMIF(TONG_HOP_LOP!$B$4:$B$15,D41,TONG_HOP_LOP!$G$4:$G$15)) | I41: =IF(D41="","",IFERROR(VLOOKUP(D41,DANH_MUC_LOP!$B$4:$O$15,14,FALSE),DIEU_KHIEN!$B$6)) | K41: =IF(B41="","",IF(J41="",I41,J41)) | L41: =IF(OR(F41="",G41=0),"",MIN(1,F41/G41)) | M41: =IF(B41="","",H41*K41*L41) | P41: =IF(B41="","",MAX(0,M41+N41-O41))
...

Sheet KT_01
A1: KẾ TOÁN LỚP - SLOT 01
A3: Chỉ số | B3: Giá trị | D3: Theo dõi | E3: Giá trị
A4: Mã lớp | B4: =IF(DANH_MUC_LOP!B4="","",DANH_MUC_LOP!B4) -> L06 | D4: Còn nợ | E4: =SUM(J14:J42) -> 0
A5: Tên lớp | B5: =IF(DANH_MUC_LOP!C4="","",DANH_MUC_LOP!C4) -> Lớp 6 Thầy Cường | D5: Giảm chuyển tháng sau | E5: =SUM(K14:K42) -> 0
A6: Số buổi lịch | B6: =IFERROR(IF(DANH_MUC_LOP!R4>0,DANH_MUC_LOP!R4,LOP_01!$B$16),0) -> 9 | D6: Thưởng HS lớp | E6: =IF(B4="",0,SUMIF(THUONG_HOC_SINH!$A$4:$A$83,B4,THUONG_HOC_SINH!$D$4:$D$83)) -> 0
A7: Học phí/buổi | B7: =IF(DANH_MUC_LOP!B4="","",DANH_MUC_LOP!F4) -> 50000
A8: Cách thu | B8: =IF(DANH_MUC_LOP!B4="","",DANH_MUC_LOP!N4) -> Theo buổi
A9: Sĩ số | B9: =COUNTIF(A14:A42,"?*") -> 18
A10: Tổng phải thu | B10: =SUM(H14:H42) -> 5025000
A11: Đã thu | B11: =SUM(I14:I42) -> 5025000
M12: Dữ liệu T8: 17 HS, 1 buổi rõ trong nguồn.
A13: Mã HS | B13: Họ tên | C13: Buổi học | D13: Buổi nghỉ | E13: Đơn giá | F13: Học phí gốc | G13: Giảm từ tháng trước | H13: Phải thu | I13: Đã thu | J13: Còn nợ | K13: Giảm chuyển tháng sau | L13: Ngày thu | M13: Ghi chú | N13: Nợ đầu kỳ | O13: Phải thu xác nhận
A14: =IFERROR(LOP_01!$A$21,"") -> HS06-001 | B14: =IFERROR(LOP_01!$B$21,"") -> Đào Thị Kim Ngân | C14: =IFERROR(LOP_01!$AH$21,"") -> 5 | D14: =IFERROR(LOP_01!$AI$21,"") -> 2 | E14: =IF(A14="","",$B$7) -> 50000 | F14: =IF(A14="","",IF($B$8="Thu trước",$B$6*E14,C14*E14)) -> 250000 | G14: =IF(A14="","",SUMIFS(CHUYEN_THANG!$D$4:$D$403,CHUYEN_THANG!$A$4:$A$403,$B$4,CHUYEN_THANG!$B$4:$B$403,A14)) -> 0 | H14: =IF(A14="","",IF(O14<>"",MAX(0,O14),MAX(0,F14-G14+N14))) -> 250000 | I14: =H14 -> 250000 | J14: =IF(A14="","",MAX(0,H14-I14)) -> 0 | K14: =IF(A14="","",IF($B$8="Thu trước",D14*E14,0)) -> 0
A15: =IFERROR(LOP_01!$A$22,"") -> HS06-002 | B15: =IFERROR(LOP_01!$B$22,"") -> Đặng Phương Anh | C15: =IFERROR(LOP_01!$AH$22,"") -> 6 | D15: =IFERROR(LOP_01!$AI$22,"") -> 1 | E15: =IF(A15="","",$B$7) -> 50000 | F15: =IF(A15="","",IF($B$8="Thu trước",$B$6*E15,C15*E15)) -> 300000 | G15: =IF(A15="","",SUMIFS(CHUYEN_THANG!$D$4:$D$403,CHUYEN_THANG!$A$4:$A$403,$B$4,CHUYEN_THANG!$B$4:$B$403,A15)) -> 0 | H15: =IF(A15="","",IF(O15<>"",MAX(0,O15),MAX(0,F15-G15+N15))) -> 300000 | I15: =H15 -> 300000 | J15: =IF(A15="","",MAX(0,H15-I15)) -> 0 | K15: =IF(A15="","",IF($B$8="Thu trước",D15*E15,0)) -> 0
A16: =IFERROR(LOP_01!$A$23,"") -> HS06-003 | B16: =IFERROR(LOP_01!$B$23,"") -> Nguyễn Gia Bảo | C16: =IFERROR(LOP_01!$AH$23,"") -> 6 | D16: =IFERROR(LOP_01!$AI$23,"") -> 1 | E16: =IF(A16="","",$B$7) -> 50000 | F16: =IF(A16="","",IF($B$8="Thu trước",$B$6*E16,C16*E16)) -> 300000 | G16: =IF(A16="","",SUMIFS(CHUYEN_THANG!$D$4:$D$403,CHUYEN_THANG!$A$4:$A$403,$B$4,CHUYEN_THANG!$B$4:$B$403,A16)) -> 0 | H16: =IF(A16="","",IF(O16<>"",MAX(0,O16),MAX(0,F16-G16+N16))) -> 300000 | I16: =H16 -> 300000 | J16: =IF(A16="","",MAX(0,H16-I16)) -> 0 | K16: =IF(A16="","",IF($B$8="Thu trước",D16*E16,0)) -> 0
A17: =IFERROR(LOP_01!$A$24,"") -> HS06-004 | B17: =IFERROR(LOP_01!$B$24,"") -> Nguyễn Đặng Gia Bảo | C17: =IFERROR(LOP_01!$AH$24,"") -> 7 | D17: =IFERROR(LOP_01!$AI$24,"") -> 0 | E17: =IF(A17="","",$B$7)/2 -> 25000 | F17: =IF(A17="","",IF($B$8="Thu trước",$B$6*E17,C17*E17)) -> 175000 | G17: =IF(A17="","",SUMIFS(CHUYEN_THANG!$D$4:$D$403,CHUYEN_THANG!$A$4:$A$403,$B$4,CHUYEN_THANG!$B$4:$B$403,A17)) -> 0 | H17: =IF(A17="","",IF(O17<>"",MAX(0,O17),MAX(0,F17-G17+N17))) -> 175000 | I17: =H17 -> 175000 | J17: =IF(A17="","",MAX(0,H17-I17)) -> 0 | K17: =IF(A17="","",IF($B$8="Thu trước",D17*E17,0)) -> 0
A18: =IFERROR(LOP_01!$A$25,"") -> HS06-005 | B18: =IFERROR(LOP_01!$B$25,"") -> Tuệ Lâm | C18: =IFERROR(LOP_01!$AH$25,"") -> 5 | D18: =IFERROR(LOP_01!$AI$25,"") -> 2 | E18: =IF(A18="","",$B$7) -> 50000 | F18: =IF(A18="","",IF($B$8="Thu trước",$B$6*E18,C18*E18)) -> 250000 | G18: =IF(A18="","",SUMIFS(CHUYEN_THANG!$D$4:$D$403,CHUYEN_THANG!$A$4:$A$403,$B$4,CHUYEN_THANG!$B$4:$B$403,A18)) -> 0 | H18: =IF(A18="","",IF(O18<>"",MAX(0,O18),MAX(0,F18-G18+N18))) -> 250000 | I18: =H18 -> 250000 | J18: =IF(A18="","",MAX(0,H18-I18)) -> 0 | K18: =IF(A18="","",IF($B$8="Thu trước",D18*E18,0)) -> 0
A19: =IFERROR(LOP_01!$A$26,"") -> HS06-006 | B19: =IFERROR(LOP_01!$B$26,"") -> Đặng Khánh Linh | C19: =IFERROR(LOP_01!$AH$26,"") -> 6 | D19: =IFERROR(LOP_01!$AI$26,"") -> 1 | E19: =IF(A19="","",$B$7) -> 50000 | F19: =IF(A19="","",IF($B$8="Thu trước",$B$6*E19,C19*E19)) -> 300000 | G19: =IF(A19="","",SUMIFS(CHUYEN_THANG!$D$4:$D$403,CHUYEN_THANG!$A$4:$A$403,$B$4,CHUYEN_THANG!$B$4:$B$403,A19)) -> 0 | H19: =IF(A19="","",IF(O19<>"",MAX(0,O19),MAX(0,F19-G19+N19))) -> 300000 | I19: =H19 -> 300000 | J19: =IF(A19="","",MAX(0,H19-I19)) -> 0 | K19: =IF(A19="","",IF($B$8="Thu trước",D19*E19,0)) -> 0
A20: =IFERROR(LOP_01!$A$27,"") -> HS06-007 | B20: =IFERROR(LOP_01!$B$27,"") -> Nguyễn Ngọc Diệp | C20: =IFERROR(LOP_01!$AH$27,"") -> 7 | D20: =IFERROR(LOP_01!$AI$27,"") -> 0 | E20: =IF(A20="","",$B$7) -> 50000 | F20: =IF(A20="","",IF($B$8="Thu trước",$B$6*E20,C20*E20)) -> 350000 | G20: =IF(A20="","",SUMIFS(CHUYEN_THANG!$D$4:$D$403,CHUYEN_THANG!$A$4:$A$403,$B$4,CHUYEN_THANG!$B$4:$B$403,A20)) -> 0 | H20: =IF(A20="","",IF(O20<>"",MAX(0,O20),MAX(0,F20-G20+N20))) -> 350000 | I20: =H20 -> 350000 | J20: =IF(A20="","",MAX(0,H20-I20)) -> 0 | K20: =IF(A20="","",IF($B$8="Thu trước",D20*E20,0)) -> 0
A21: =IFERROR(LOP_01!$A$28,"") -> HS06-008 | B21: =IFERROR(LOP_01!$B$28,"") -> Nguyễn Ngọc Cẩm Tú | C21: =IFERROR(LOP_01!$AH$28,"") -> 5 | D21: =IFERROR(LOP_01!$AI$28,"") -> 2 | E21: =IF(A21="","",$B$7) -> 50000 | F21: =IF(A21="","",IF($B$8="Thu trước",$B$6*E21,C21*E21)) -> 250000 | G21: =IF(A21="","",SUMIFS(CHUYEN_THANG!$D$4:$D$403,CHUYEN_THANG!$A$4:$A$403,$B$4,CHUYEN_THANG!$B$4:$B$403,A21)) -> 0 | H21: =IF(A21="","",IF(O21<>"",MAX(0,O21),MAX(0,F21-G21+N21))) -> 250000 | I21: =H21 -> 250000 | J21: =IF(A21="","",MAX(0,H21-I21)) -> 0 | K21: =IF(A21="","",IF($B$8="Thu trước",D21*E21,0)) -> 0
A22: =IFERROR(LOP_01!$A$29,"") -> HS06-009 | B22: =IFERROR(LOP_01!$B$29,"") -> Đào Thế Hoàng | C22: =IFERROR(LOP_01!$AH$29,"") -> 6 | D22: =IFERROR(LOP_01!$AI$29,"") -> 1 | E22: =IF(A22="","",$B$7) -> 50000 | F22: =IF(A22="","",IF($B$8="Thu trước",$B$6*E22,C22*E22)) -> 300000 | G22: =IF(A22="","",SUMIFS(CHUYEN_THANG!$D$4:$D$403,CHUYEN_THANG!$A$4:$A$403,$B$4,CHUYEN_THANG!$B$4:$B$403,A22)) -> 0 | H22: =IF(A22="","",IF(O22<>"",MAX(0,O22),MAX(0,F22-G22+N22))) -> 300000 | I22: =H22 -> 300000 | J22: =IF(A22="","",MAX(0,H22-I22)) -> 0 | K22: =IF(A22="","",IF($B$8="Thu trước",D22*E22,0)) -> 0
A23: =IFERROR(LOP_01!$A$30,"") -> HS06-010 | B23: =IFERROR(LOP_01!$B$30,"") -> Đào Nguyễn Bình An | C23: =IFERROR(LOP_01!$AH$30,"") -> 7 | D23: =IFERROR(LOP_01!$AI$30,"") -> 0 | E23: =IF(A23="","",$B$7) -> 50000 | F23: =IF(A23="","",IF($B$8="Thu trước",$B$6*E23,C23*E23)) -> 350000 | G23: =IF(A23="","",SUMIFS(CHUYEN_THANG!$D$4:$D$403,CHUYEN_THANG!$A$4:$A$403,$B$4,CHUYEN_THANG!$B$4:$B$403,A23)) -> 0 | H23: =IF(A23="","",IF(O23<>"",MAX(0,O23),MAX(0,F23-G23+N23))) -> 350000 | I23: =H23 -> 350000 | J23: =IF(A23="","",MAX(0,H23-I23)) -> 0 | K23: =IF(A23="","",IF($B$8="Thu trước",D23*E23,0)) -> 0
A24: =IFERROR(LOP_01!$A$31,"") -> HS06-011 | B24: =IFERROR(LOP_01!$B$31,"") -> Nguyễn Trà My | C24: =IFERROR(LOP_01!$AH$31,"") -> 6 | D24: =IFERROR(LOP_01!$AI$31,"") -> 1 | E24: =IF(A24="","",$B$7) -> 50000 | F24: =IF(A24="","",IF($B$8="Thu trước",$B$6*E24,C24*E24)) -> 300000 | G24: =IF(A24="","",SUMIFS(CHUYEN_THANG!$D$4:$D$403,CHUYEN_THANG!$A$4:$A$403,$B$4,CHUYEN_THANG!$B$4:$B$403,A24)) -> 0 | H24: =IF(A24="","",IF(O24<>"",MAX(0,O24),MAX(0,F24-G24+N24))) -> 300000 | I24: =H24 -> 300000 | J24: =IF(A24="","",MAX(0,H24-I24)) -> 0 | K24: =IF(A24="","",IF($B$8="Thu trước",D24*E24,0)) -> 0
A25: =IFERROR(LOP_01!$A$32,"") -> HS06-012 | B25: =IFERROR(LOP_01!$B$32,"") -> Bảo Dũng | C25: =IFERROR(LOP_01!$AH$32,"") -> 6 | D25: =IFERROR(LOP_01!$AI$32,"") -> 1 | E25: =IF(A25="","",$B$7) -> 50000 | F25: =IF(A25="","",IF($B$8="Thu trước",$B$6*E25,C25*E25)) -> 300000 | G25: =IF(A25="","",SUMIFS(CHUYEN_THANG!$D$4:$D$403,CHUYEN_THANG!$A$4:$A$403,$B$4,CHUYEN_THANG!$B$4:$B$403,A25)) -> 0 | H25: =IF(A25="","",IF(O25<>"",MAX(0,O25),MAX(0,F25-G25+N25))) -> 300000 | I25: =H25 -> 300000 | J25: =IF(A25="","",MAX(0,H25-I25)) -> 0 | K25: =IF(A25="","",IF($B$8="Thu trước",D25*E25,0)) -> 0
A26: =IFERROR(LOP_01!$A$33,"") -> HS06-013 | B26: =IFERROR(LOP_01!$B$33,"") -> Đào Quang Minh | C26: =IFERROR(LOP_01!$AH$33,"") -> 5 | D26: =IFERROR(LOP_01!$AI$33,"") -> 2 | E26: =IF(A26="","",$B$7) -> 50000 | F26: =IF(A26="","",IF($B$8="Thu trước",$B$6*E26,C26*E26)) -> 250000 | G26: =IF(A26="","",SUMIFS(CHUYEN_THANG!$D$4:$D$403,CHUYEN_THANG!$A$4:$A$403,$B$4,CHUYEN_THANG!$B$4:$B$403,A26)) -> 0 | H26: =IF(A26="","",IF(O26<>"",MAX(0,O26),MAX(0,F26-G26+N26))) -> 250000 | I26: =H26 -> 250000 | J26: =IF(A26="","",MAX(0,H26-I26)) -> 0 | K26: =IF(A26="","",IF($B$8="Thu trước",D26*E26,0)) -> 0
A27: =IFERROR(LOP_01!$A$34,"") -> HS06-014 | B27: =IFERROR(LOP_01!$B$34,"") -> Duy | C27: =IFERROR(LOP_01!$AH$34,"") -> 5 | D27: =IFERROR(LOP_01!$AI$34,"") -> 2 | E27: =IF(A27="","",$B$7) -> 50000 | F27: =IF(A27="","",IF($B$8="Thu trước",$B$6*E27,C27*E27)) -> 250000 | G27: =IF(A27="","",SUMIFS(CHUYEN_THANG!$D$4:$D$403,CHUYEN_THANG!$A$4:$A$403,$B$4,CHUYEN_THANG!$B$4:$B$403,A27)) -> 0 | H27: =IF(A27="","",IF(O27<>"",MAX(0,O27),MAX(0,F27-G27+N27))) -> 250000 | I27: =H27 -> 250000 | J27: =IF(A27="","",MAX(0,H27-I27)) -> 0 | K27: =IF(A27="","",IF($B$8="Thu trước",D27*E27,0)) -> 0
A28: =IFERROR(LOP_01!$A$35,"") -> HS06-015 | B28: =IFERROR(LOP_01!$B$35,"") -> Phúc | C28: =IFERROR(LOP_01!$AH$35,"") -> 7 | D28: =IFERROR(LOP_01!$AI$35,"") -> 0 | E28: =IF(A28="","",$B$7) -> 50000 | F28: =IF(A28="","",IF($B$8="Thu trước",$B$6*E28,C28*E28)) -> 350000 | G28: =IF(A28="","",SUMIFS(CHUYEN_THANG!$D$4:$D$403,CHUYEN_THANG!$A$4:$A$403,$B$4,CHUYEN_THANG!$B$4:$B$403,A28)) -> 0 | H28: =IF(A28="","",IF(O28<>"",MAX(0,O28),MAX(0,F28-G28+N28))) -> 350000 | I28: =H28 -> 350000 | J28: =IF(A28="","",MAX(0,H28-I28)) -> 0 | K28: =IF(A28="","",IF($B$8="Thu trước",D28*E28,0)) -> 0
A29: =IFERROR(LOP_01!$A$36,"") -> HS06-016 | B29: =IFERROR(LOP_01!$B$36,"") -> Linh | C29: =IFERROR(LOP_01!$AH$36,"") -> 4 | D29: =IFERROR(LOP_01!$AI$36,"") -> 3 | E29: =IF(A29="","",$B$7) -> 50000 | F29: =IF(A29="","",IF($B$8="Thu trước",$B$6*E29,C29*E29)) -> 200000 | G29: =IF(A29="","",SUMIFS(CHUYEN_THANG!$D$4:$D$403,CHUYEN_THANG!$A$4:$A$403,$B$4,CHUYEN_THANG!$B$4:$B$403,A29)) -> 0 | H29: =IF(A29="","",IF(O29<>"",MAX(0,O29),MAX(0,F29-G29+N29))) -> 200000 | I29: =H29 -> 200000 | J29: =IF(A29="","",MAX(0,H29-I29)) -> 0 | K29: =IF(A29="","",IF($B$8="Thu trước",D29*E29,0)) -> 0
A30: =IFERROR(LOP_01!$A$37,"") -> HS06-017 | B30: =IFERROR(LOP_01!$B$37,"") -> Hân | C30: =IFERROR(LOP_01!$AH$37,"") -> 6 | D30: =IFERROR(LOP_01!$AI$37,"") -> 0 | E30: =IF(A30="","",$B$7) -> 50000 | F30: =IF(A30="","",IF($B$8="Thu trước",$B$6*E30,C30*E30)) -> 300000 | G30: =IF(A30="","",SUMIFS(CHUYEN_THANG!$D$4:$D$403,CHUYEN_THANG!$A$4:$A$403,$B$4,CHUYEN_THANG!$B$4:$B$403,A30)) -> 0 | H30: =IF(A30="","",IF(O30<>"",MAX(0,O30),MAX(0,F30-G30+N30))) -> 300000 | I30: =H30 -> 300000 | J30: =IF(A30="","",MAX(0,H30-I30)) -> 0 | K30: =IF(A30="","",IF($B$8="Thu trước",D30*E30,0)) -> 0
A31: =IFERROR(LOP_01!$A$38,"") -> HS06-018 | B31: =IFERROR(LOP_01!$B$38,"") -> Kiều Anh | C31: =IFERROR(LOP_01!$AH$38,"") -> 5 | D31: =IFERROR(LOP_01!$AI$38,"") -> 1 | E31: =IF(A31="","",$B$7) -> 50000 | F31: =IF(A31="","",IF($B$8="Thu trước",$B$6*E31,C31*E31)) -> 250000 | G31: =IF(A31="","",SUMIFS(CHUYEN_THANG!$D$4:$D$403,CHUYEN_THANG!$A$4:$A$403,$B$4,CHUYEN_THANG!$B$4:$B$403,A31)) -> 0 | H31: =IF(A31="","",IF(O31<>"",MAX(0,O31),MAX(0,F31-G31+N31))) -> 250000 | I31: =H31 -> 250000 | J31: =IF(A31="","",MAX(0,H31-I31)) -> 0 | K31: =IF(A31="","",IF($B$8="Thu trước",D31*E31,0)) -> 0
A32: =IFERROR(LOP_01!$A$39,"") | B32: =IFERROR(LOP_01!$B$39,"") | C32: =IFERROR(LOP_01!$AH$39,"") | D32: =IFERROR(LOP_01!$AI$39,"") | E32: =IF(A32="","",$B$7) | F32: =IF(A32="","",IF($B$8="Thu trước",$B$6*E32,C32*E32)) | G32: =IF(A32="","",SUMIFS(CHUYEN_THANG!$D$4:$D$403,CHUYEN_THANG!$A$4:$A$403,$B$4,CHUYEN_THANG!$B$4:$B$403,A32)) | H32: =IF(A32="","",IF(O32<>"",MAX(0,O32),MAX(0,F32-G32+N32))) | J32: =IF(A32="","",MAX(0,H32-I32)) | K32: =IF(A32="","",IF($B$8="Thu trước",D32*E32,0))
A33: =IFERROR(LOP_01!$A$40,"") | B33: =IFERROR(LOP_01!$B$40,"") | C33: =IFERROR(LOP_01!$AH$40,"") | D33: =IFERROR(LOP_01!$AI$40,"") | E33: =IF(A33="","",$B$7) | F33: =IF(A33="","",IF($B$8="Thu trước",$B$6*E33,C33*E33)) | G33: =IF(A33="","",SUMIFS(CHUYEN_THANG!$D$4:$D$403,CHUYEN_THANG!$A$4:$A$403,$B$4,CHUYEN_THANG!$B$4:$B$403,A33)) | H33: =IF(A33="","",IF(O33<>"",MAX(0,O33),MAX(0,F33-G33+N33))) | J33: =IF(A33="","",MAX(0,H33-I33)) | K33: =IF(A33="","",IF($B$8="Thu trước",D33*E33,0))
A34: =IFERROR(LOP_01!$A$41,"") | B34: =IFERROR(LOP_01!$B$41,"") | C34: =IFERROR(LOP_01!$AH$41,"") | D34: =IFERROR(LOP_01!$AI$41,"") | E34: =IF(A34="","",$B$7) | F34: =IF(A34="","",IF($B$8="Thu trước",$B$6*E34,C34*E34)) | G34: =IF(A34="","",SUMIFS(CHUYEN_THANG!$D$4:$D$403,CHUYEN_THANG!$A$4:$A$403,$B$4,CHUYEN_THANG!$B$4:$B$403,A34)) | H34: =IF(A34="","",IF(O34<>"",MAX(0,O34),MAX(0,F34-G34+N34))) | J34: =IF(A34="","",MAX(0,H34-I34)) | K34: =IF(A34="","",IF($B$8="Thu trước",D34*E34,0))
A35: =IFERROR(LOP_01!$A$42,"") | B35: =IFERROR(LOP_01!$B$42,"") | C35: =IFERROR(LOP_01!$AH$42,"") | D35: =IFERROR(LOP_01!$AI$42,"") | E35: =IF(A35="","",$B$7) | F35: =IF(A35="","",IF($B$8="Thu trước",$B$6*E35,C35*E35)) | G35: =IF(A35="","",SUMIFS(CHUYEN_THANG!$D$4:$D$403,CHUYEN_THANG!$A$4:$A$403,$B$4,CHUYEN_THANG!$B$4:$B$403,A35)) | H35: =IF(A35="","",IF(O35<>"",MAX(0,O35),MAX(0,F35-G35+N35))) | J35: =IF(A35="","",MAX(0,H35-I35)) | K35: =IF(A35="","",IF($B$8="Thu trước",D35*E35,0))
A36: =IFERROR(LOP_01!$A$43,"") | B36: =IFERROR(LOP_01!$B$43,"") | C36: =IFERROR(LOP_01!$AH$43,"") | D36: =IFERROR(LOP_01!$AI$43,"") | E36: =IF(A36="","",$B$7) | F36: =IF(A36="","",IF($B$8="Thu trước",$B$6*E36,C36*E36)) | G36: =IF(A36="","",SUMIFS(CHUYEN_THANG!$D$4:$D$403,CHUYEN_THANG!$A$4:$A$403,$B$4,CHUYEN_THANG!$B$4:$B$403,A36)) | H36: =IF(A36="","",IF(O36<>"",MAX(0,O36),MAX(0,F36-G36+N36))) | J36: =IF(A36="","",MAX(0,H36-I36)) | K36: =IF(A36="","",IF($B$8="Thu trước",D36*E36,0))
A37: =IFERROR(LOP_01!$A$44,"") | B37: =IFERROR(LOP_01!$B$44,"") | C37: =IFERROR(LOP_01!$AH$44,"") | D37: =IFERROR(LOP_01!$AI$44,"") | E37: =IF(A37="","",$B$7) | F37: =IF(A37="","",IF($B$8="Thu trước",$B$6*E37,C37*E37)) | G37: =IF(A37="","",SUMIFS(CHUYEN_THANG!$D$4:$D$403,CHUYEN_THANG!$A$4:$A$403,$B$4,CHUYEN_THANG!$B$4:$B$403,A37)) | H37: =IF(A37="","",IF(O37<>"",MAX(0,O37),MAX(0,F37-G37+N37))) | J37: =IF(A37="","",MAX(0,H37-I37)) | K37: =IF(A37="","",IF($B$8="Thu trước",D37*E37,0))
A38: =IFERROR(LOP_01!$A$45,"") | B38: =IFERROR(LOP_01!$B$45,"") | C38: =IFERROR(LOP_01!$AH$45,"") | D38: =IFERROR(LOP_01!$AI$45,"") | E38: =IF(A38="","",$B$7) | F38: =IF(A38="","",IF($B$8="Thu trước",$B$6*E38,C38*E38)) | G38: =IF(A38="","",SUMIFS(CHUYEN_THANG!$D$4:$D$403,CHUYEN_THANG!$A$4:$A$403,$B$4,CHUYEN_THANG!$B$4:$B$403,A38)) | H38: =IF(A38="","",IF(O38<>"",MAX(0,O38),MAX(0,F38-G38+N38))) | J38: =IF(A38="","",MAX(0,H38-I38)) | K38: =IF(A38="","",IF($B$8="Thu trước",D38*E38,0))
A39: =IFERROR(LOP_01!$A$46,"") | B39: =IFERROR(LOP_01!$B$46,"") | C39: =IFERROR(LOP_01!$AH$46,"") | D39: =IFERROR(LOP_01!$AI$46,"") | E39: =IF(A39="","",$B$7) | F39: =IF(A39="","",IF($B$8="Thu trước",$B$6*E39,C39*E39)) | G39: =IF(A39="","",SUMIFS(CHUYEN_THANG!$D$4:$D$403,CHUYEN_THANG!$A$4:$A$403,$B$4,CHUYEN_THANG!$B$4:$B$403,A39)) | H39: =IF(A39="","",IF(O39<>"",MAX(0,O39),MAX(0,F39-G39+N39))) | J39: =IF(A39="","",MAX(0,H39-I39)) | K39: =IF(A39="","",IF($B$8="Thu trước",D39*E39,0))
A40: =IFERROR(LOP_01!$A$47,"") | B40: =IFERROR(LOP_01!$B$47,"") | C40: =IFERROR(LOP_01!$AH$47,"") | D40: =IFERROR(LOP_01!$AI$47,"") | E40: =IF(A40="","",$B$7) | F40: =IF(A40="","",IF($B$8="Thu trước",$B$6*E40,C40*E40)) | G40: =IF(A40="","",SUMIFS(CHUYEN_THANG!$D$4:$D$403,CHUYEN_THANG!$A$4:$A$403,$B$4,CHUYEN_THANG!$B$4:$B$403,A40)) | H40: =IF(A40="","",IF(O40<>"",MAX(0,O40),MAX(0,F40-G40+N40))) | J40: =IF(A40="","",MAX(0,H40-I40)) | K40: =IF(A40="","",IF($B$8="Thu trước",D40*E40,0))
A41: =IFERROR(LOP_01!$A$48,"") | B41: =IFERROR(LOP_01!$B$48,"") | C41: =IFERROR(LOP_01!$AH$48,"") | D41: =IFERROR(LOP_01!$AI$48,"") | E41: =IF(A41="","",$B$7) | F41: =IF(A41="","",IF($B$8="Thu trước",$B$6*E41,C41*E41)) | G41: =IF(A41="","",SUMIFS(CHUYEN_THANG!$D$4:$D$403,CHUYEN_THANG!$A$4:$A$403,$B$4,CHUYEN_THANG!$B$4:$B$403,A41)) | H41: =IF(A41="","",IF(O41<>"",MAX(0,O41),MAX(0,F41-G41+N41))) | J41: =IF(A41="","",MAX(0,H41-I41)) | K41: =IF(A41="","",IF($B$8="Thu trước",D41*E41,0))
...

Sheet KT_02
A1: KẾ TOÁN LỚP - SLOT 02
A3: Chỉ số | B3: Giá trị | D3: Theo dõi | E3: Giá trị
A4: Mã lớp | B4: =IF(DANH_MUC_LOP!B5="","",DANH_MUC_LOP!B5) -> L07 | D4: Còn nợ | E4: =SUM(J14:J43) -> 0
A5: Tên lớp | B5: =IF(DANH_MUC_LOP!C5="","",DANH_MUC_LOP!C5) -> Toán 7 Thầy Cường | D5: Giảm chuyển tháng sau | E5: =SUM(K14:K43) -> 0
A6: Số buổi lịch | B6: =IFERROR(IF(DANH_MUC_LOP!R5>0,DANH_MUC_LOP!R5,LOP_02!$B$16),0) -> 8 | D6: Thưởng HS lớp | E6: =IF(B4="",0,SUMIF(THUONG_HOC_SINH!$A$4:$A$83,B4,THUONG_HOC_SINH!$D$4:$D$83)) -> 0
A7: Học phí/buổi | B7: =IF(DANH_MUC_LOP!B5="","",DANH_MUC_LOP!F5) -> 50000
A8: Cách thu | B8: =IF(DANH_MUC_LOP!B5="","",DANH_MUC_LOP!N5) -> Theo buổi
A9: Sĩ số | B9: =COUNTIF(A14:A43,"?*") -> 13
A10: Tổng phải thu | B10: =SUM(H14:H43) -> 2600000
A11: Đã thu | B11: =SUM(I14:I43) -> 2600000
M12: Dữ liệu T8: roster 12 HS; 1 block điểm danh thực tế được lấy.
A13: Mã HS | B13: Họ tên | C13: Buổi học | D13: Buổi nghỉ | E13: Đơn giá | F13: Học phí gốc | G13: Giảm từ tháng trước | H13: Phải thu | I13: Đã thu | J13: Còn nợ | K13: Giảm chuyển tháng sau | L13: Ngày thu | M13: Ghi chú | N13: Nợ đầu kỳ | O13: Phải thu xác nhận
A14: =IFERROR(LOP_02!$A$21,"") -> HS07-001 | B14: =IFERROR(LOP_02!$B$21,"") -> Lê Ngọc Ánh | C14: =IFERROR(LOP_02!$AH$21,"") -> 5 | D14: =IFERROR(LOP_02!$AI$21,"") -> 0 | E14: =IF(A14="","",$B$7) -> 50000 | F14: =IF(A14="","",IF($B$8="Thu trước",$B$6*E14,C14*E14)) -> 250000 | G14: =IF(A14="","",SUMIFS(CHUYEN_THANG!$D$4:$D$403,CHUYEN_THANG!$A$4:$A$403,$B$4,CHUYEN_THANG!$B$4:$B$403,A14)) -> 0 | H14: =IF(A14="","",IF(O14<>"",MAX(0,O14),MAX(0,F14-G14+N14))) -> 250000 | I14: =H14 -> 250000 | J14: =IF(A14="","",MAX(0,H14-I14)) -> 0 | K14: =IF(A14="","",IF($B$8="Thu trước",D14*E14,0)) -> 0
A15: =IFERROR(LOP_02!$A$22,"") -> HS07-002 | B15: =IFERROR(LOP_02!$B$22,"") -> Nguyễn Thị Hồng Hạnh | C15: =IFERROR(LOP_02!$AH$22,"") -> 5 | D15: =IFERROR(LOP_02!$AI$22,"") -> 0 | E15: =IF(A15="","",$B$7) -> 50000 | F15: =IF(A15="","",IF($B$8="Thu trước",$B$6*E15,C15*E15)) -> 250000 | G15: =IF(A15="","",SUMIFS(CHUYEN_THANG!$D$4:$D$403,CHUYEN_THANG!$A$4:$A$403,$B$4,CHUYEN_THANG!$B$4:$B$403,A15)) -> 0 | H15: =IF(A15="","",IF(O15<>"",MAX(0,O15),MAX(0,F15-G15+N15))) -> 250000 | I15: =H15 -> 250000 | J15: =IF(A15="","",MAX(0,H15-I15)) -> 0 | K15: =IF(A15="","",IF($B$8="Thu trước",D15*E15,0)) -> 0
